<?xml version="1.0" ?>
<sdf version="1.7">
  <model name="simple_pendulum">
    <link name="arm">
      <pose>0 0 0.5 0 0 0</pose> <inertial>
        <mass>0.1</mass> <inertia>
          <ixx>0.001</ixx>
          <iyy>0.001</iyy>
          <izz>0.001</izz>
          <ixy>0</ixy>
          <ixz>0</ixz>
          <iyz>0</iyz>
        </inertia>
      </inertial>
      <visual name="visual">
        <geometry>
          <cylinder>
            <radius>0.01</radius>
            <length>1</length>
          </cylinder>
        </geometry>
        <material>
          <ambient>0 0 1 1</ambient> <diffuse>0 0 1 1</diffuse>
          <specular>0 0 1 1</specular>
          <emissive>0 0 0 1</emissive>
        </material>
      </visual>
      <collision name="collision">
        <geometry>
          <cylinder>
            <radius>0.01</radius>
            <length>1</length>
          </cylinder>
        </geometry>
      </collision>
    </link>

    <link name="bob">
      <pose>0 0 1 0 0 0</pose> <inertial>
        <mass>0.5</mass> <inertia>
          <ixx>0.01</ixx>
          <iyy>0.01</iyy>
          <izz>0.01</izz>
          <ixy>0</ixy>
          <ixz>0</ixz>
          <iyz>0</iyz>
        </inertia>
      </inertial>
      <visual name="visual">
        <geometry>
          <sphere>
            <radius>0.05</radius>
          </sphere>
        </geometry>
        <material>
          <ambient>1 0 0 1</ambient> <diffuse>1 0 0 1</diffuse>
          <specular>1 0 0 1</specular>
          <emissive>0 0 0 1</emissive>
        </material>
      </visual>
      <collision name="collision">
        <geometry>
          <sphere>
            <radius>0.05</radius>
          </sphere>
        </geometry>
      </collision>
    </link>

    <joint name="arm_bob_joint" type="revolute">
      <parent>arm</parent>
      <child>bob</child>
      <axis>
        <xyz>0 1 0</xyz> 
        <limit>
          <lower>-1e16</lower>
          <upper>1e16</upper>
        </limit>
      </axis>
      <pose>0 0 1 0 0 0</pose> 
    </joint>
  </model>
</sdf>