<?xml version="1.0" ?>
<!-- =================================================================================== -->
<!-- |    This document was autogenerated by xacro from worlds/world.xacro             | -->
<!-- |    EDITING THIS FILE BY HAND IS NOT RECOMMENDED                                 | -->
<!-- =================================================================================== -->
<sdf version="1.7">
  <world name="default">
    <gravity> 0 0 -9.81 </gravity>
    <model name="ground_plane">
      <static>true</static>
      <link name="link">
        <collision name="collision">
          <geometry>
            <plane>
              <normal>0 0 1</normal>
            </plane>
          </geometry>
        </collision>
        <visual name="visual">
          <geometry>
            <plane>
              <normal>0 0 1</normal>
              <size>100 100</size>
            </plane>
          </geometry>
          <material>
            <ambient>0.8 0.8 0.8 1</ambient>
            <diffuse>0.8 0.8 0.8 1</diffuse>
            <specular>0.8 0.8 0.8 1</specular>
          </material>
        </visual>
      </link>
    </model>
    <model name="simple_pendulum_0">
      <pose>0 0 1.31 0 0 0</pose>
      <link name="base_link">
        <pose>0 0 -0.65 0 0 0</pose>
        <inertial>
          <mass>1000</mass>
          <inertia>
            <ixx>146.04166666666669</ixx>
            <iyy>146.04166666666669</iyy>
            <izz>10.416666666666666</izz>
            <ixy>0</ixy>
            <ixz>0</ixz>
            <iyz>0</iyz>
          </inertia>
        </inertial>
        <visual name="visual">
          <geometry>
            <box>
              <size>0.25 0.25 1.3 </size>
            </box>
          </geometry>
          <material>
            <ambient>0 0 1 1</ambient>
            <diffuse>0 0 1 1</diffuse>
            <specular>0 0 1 1</specular>
            <emissive>0 0 1 1</emissive>
          </material>
        </visual>
        <collision name="collision">
          <geometry>
            <box>
              <size>0.25 0.25 1.3 </size>
            </box>
          </geometry>
        </collision>
      </link>
      <link name="arm_holder">
        <pose>-0.0675 0 0 0 0 0</pose>
        <inertial>
          <mass>0.1</mass>
          <inertia>
            <ixx>1.6666666666666669e-06</ixx>
            <iyy>0.00015270833333333334</iyy>
            <izz>0.00015270833333333334</izz>
            <ixy>0</ixy>
            <ixz>0</ixz>
            <iyz>0</iyz>
          </inertia>
        </inertial>
        <visual name="visual">
          <geometry>
            <box>
              <size>0.135 0.01 0.01 </size>
            </box>
          </geometry>
          <material>
            <ambient>0 0 1 1</ambient>
            <diffuse>0 0 1 1</diffuse>
            <specular>0 0 1 1</specular>
            <emissive>0 0 1 1</emissive>
          </material>
        </visual>
        <collision name="collision">
          <geometry>
            <box>
              <size>0.135 0.01 0.01 </size>
            </box>
          </geometry>
        </collision>
      </link>
      <link name="arm">
        <pose>-0.145 0.19470917115432526 -0.46053049700144255 0.4 0 0</pose>
        <inertial>
          <mass>0.1</mass>
          <inertia>
            <ixx>0.008355833333333333</ixx>
            <iyy>0.008355833333333333</iyy>
            <izz>4.5e-05</izz>
            <ixy>0</ixy>
            <ixz>0</ixz>
            <iyz>0</iyz>
          </inertia>
        </inertial>
        <visual name="visual">
          <geometry>
            <cylinder>
              <radius>0.03</radius>
              <length>1.0</length>
            </cylinder>
          </geometry>
          <material>
            <ambient>1 0 0 1</ambient>
            <diffuse>1 0 0 1</diffuse>
            <specular>1 0 0 1</specular>
            <emissive>1 0 0 1</emissive>
          </material>
        </visual>
        <collision name="collision">
          <geometry>
            <cylinder>
              <radius>0.03</radius>
              <length>1.0</length>
            </cylinder>
          </geometry>
        </collision>
      </link>
      <link name="bob">
        <pose>-0.145 0.3894183423086505 -0.9210609940028851 0 0 0</pose>
        <inertial>
          <mass>5</mass>
          <inertia>
            <ixx>0.020000000000000004</ixx>
            <iyy>0.020000000000000004</iyy>
            <izz>0.020000000000000004</izz>
            <ixy>0</ixy>
            <ixz>0</ixz>
            <iyz>0</iyz>
          </inertia>
        </inertial>
        <visual name="visual">
          <geometry>
            <sphere>
              <radius>0.1</radius>
            </sphere>
          </geometry>
          <material>
            <ambient>0 1 0 1</ambient>
            <diffuse>0 1 0 1</diffuse>
            <specular>0 1 0 1</specular>
            <emissive>0 1 0 1</emissive>
          </material>
        </visual>
        <collision name="collision">
          <geometry>
            <sphere>
              <radius>0.1</radius>
            </sphere>
          </geometry>
        </collision>
      </link>
      <joint name="arm_joint_0" type="revolute">
        <parent>arm_holder</parent>
        <child>arm</child>
        <pose>0 0 0.5 0 0 0</pose>
        <axis>
          <xyz>1 0 0</xyz>
          <limit>
            <lower>-1e4</lower>
            <upper>1e4</upper>
          </limit>
          <dynamics>
            <damping>5</damping>
            <friction>0.0</friction>
          </dynamics>
        </axis>
      </joint>
      <joint name="arm_holder_joint" type="fixed">
        <parent>base_link</parent>
        <child>arm_holder</child>
      </joint>
      <joint name="bob_joint" type="fixed">
        <parent>arm</parent>
        <child>bob</child>
      </joint>
      <plugin filename="libPID_Pendulum" name="simp_pend_ctrl::PID_Pendulum">
        <joint_name>arm_joint_0</joint_name>
        <p_gain>200.0</p_gain>
        <i_gain>0.5</i_gain>
        <d_gain>50.0</d_gain>
        <target_position>3.14159</target_position>
        <theta_0>0.4</theta_0>
      </plugin>
      <!--
            <plugin filename="libGravity_Invert"
                name="simp_pend_ctrl::Gravity_Invert">
                <joint_name>arm_joint_${n}</joint_name>
                <bob_mass>${bob_mass} </bob_mass>
                <arm_length>${arm_length}</arm_length>
                <theta_0>${theta_0} </theta_0>
                <n>${n}</n>
            </plugin>
            -->
    </model>
    <model name="simple_pendulum_1">
      <pose>2 0 1.31 0 0 0</pose>
      <link name="base_link">
        <pose>0 0 -0.65 0 0 0</pose>
        <inertial>
          <mass>1000</mass>
          <inertia>
            <ixx>146.04166666666669</ixx>
            <iyy>146.04166666666669</iyy>
            <izz>10.416666666666666</izz>
            <ixy>0</ixy>
            <ixz>0</ixz>
            <iyz>0</iyz>
          </inertia>
        </inertial>
        <visual name="visual">
          <geometry>
            <box>
              <size>0.25 0.25 1.3 </size>
            </box>
          </geometry>
          <material>
            <ambient>0 0 1 1</ambient>
            <diffuse>0 0 1 1</diffuse>
            <specular>0 0 1 1</specular>
            <emissive>0 0 1 1</emissive>
          </material>
        </visual>
        <collision name="collision">
          <geometry>
            <box>
              <size>0.25 0.25 1.3 </size>
            </box>
          </geometry>
        </collision>
      </link>
      <link name="arm_holder">
        <pose>-0.0675 0 0 0 0 0</pose>
        <inertial>
          <mass>0.1</mass>
          <inertia>
            <ixx>1.6666666666666669e-06</ixx>
            <iyy>0.00015270833333333334</iyy>
            <izz>0.00015270833333333334</izz>
            <ixy>0</ixy>
            <ixz>0</ixz>
            <iyz>0</iyz>
          </inertia>
        </inertial>
        <visual name="visual">
          <geometry>
            <box>
              <size>0.135 0.01 0.01 </size>
            </box>
          </geometry>
          <material>
            <ambient>0 0 1 1</ambient>
            <diffuse>0 0 1 1</diffuse>
            <specular>0 0 1 1</specular>
            <emissive>0 0 1 1</emissive>
          </material>
        </visual>
        <collision name="collision">
          <geometry>
            <box>
              <size>0.135 0.01 0.01 </size>
            </box>
          </geometry>
        </collision>
      </link>
      <link name="arm">
        <pose>-0.145 -0.2823212366975177 -0.41266780745483916 -0.6 0 0</pose>
        <inertial>
          <mass>0.1</mass>
          <inertia>
            <ixx>0.008355833333333333</ixx>
            <iyy>0.008355833333333333</iyy>
            <izz>4.5e-05</izz>
            <ixy>0</ixy>
            <ixz>0</ixz>
            <iyz>0</iyz>
          </inertia>
        </inertial>
        <visual name="visual">
          <geometry>
            <cylinder>
              <radius>0.03</radius>
              <length>1.0</length>
            </cylinder>
          </geometry>
          <material>
            <ambient>1 0 0 1</ambient>
            <diffuse>1 0 0 1</diffuse>
            <specular>1 0 0 1</specular>
            <emissive>1 0 0 1</emissive>
          </material>
        </visual>
        <collision name="collision">
          <geometry>
            <cylinder>
              <radius>0.03</radius>
              <length>1.0</length>
            </cylinder>
          </geometry>
        </collision>
      </link>
      <link name="bob">
        <pose>-0.145 -0.5646424733950354 -0.8253356149096783 0 0 0</pose>
        <inertial>
          <mass>5</mass>
          <inertia>
            <ixx>0.020000000000000004</ixx>
            <iyy>0.020000000000000004</iyy>
            <izz>0.020000000000000004</izz>
            <ixy>0</ixy>
            <ixz>0</ixz>
            <iyz>0</iyz>
          </inertia>
        </inertial>
        <visual name="visual">
          <geometry>
            <sphere>
              <radius>0.1</radius>
            </sphere>
          </geometry>
          <material>
            <ambient>0 1 0 1</ambient>
            <diffuse>0 1 0 1</diffuse>
            <specular>0 1 0 1</specular>
            <emissive>0 1 0 1</emissive>
          </material>
        </visual>
        <collision name="collision">
          <geometry>
            <sphere>
              <radius>0.1</radius>
            </sphere>
          </geometry>
        </collision>
      </link>
      <joint name="arm_joint_1" type="revolute">
        <parent>arm_holder</parent>
        <child>arm</child>
        <pose>0 0 0.5 0 0 0</pose>
        <axis>
          <xyz>1 0 0</xyz>
          <limit>
            <lower>-1e4</lower>
            <upper>1e4</upper>
          </limit>
          <dynamics>
            <damping>5</damping>
            <friction>0.0</friction>
          </dynamics>
        </axis>
      </joint>
      <joint name="arm_holder_joint" type="fixed">
        <parent>base_link</parent>
        <child>arm_holder</child>
      </joint>
      <joint name="bob_joint" type="fixed">
        <parent>arm</parent>
        <child>bob</child>
      </joint>
      <plugin filename="libPID_Pendulum" name="simp_pend_ctrl::PID_Pendulum">
        <joint_name>arm_joint_1</joint_name>
        <p_gain>200.0</p_gain>
        <i_gain>0.5</i_gain>
        <d_gain>50.0</d_gain>
        <target_position>3.14159</target_position>
        <theta_0>-0.6</theta_0>
      </plugin>
      <!--
            <plugin filename="libGravity_Invert"
                name="simp_pend_ctrl::Gravity_Invert">
                <joint_name>arm_joint_${n}</joint_name>
                <bob_mass>${bob_mass} </bob_mass>
                <arm_length>${arm_length}</arm_length>
                <theta_0>${theta_0} </theta_0>
                <n>${n}</n>
            </plugin>
            -->
    </model>
    <model name="simple_pendulum_2">
      <pose>4 0 1.31 0 0 0</pose>
      <link name="base_link">
        <pose>0 0 -0.65 0 0 0</pose>
        <inertial>
          <mass>1000</mass>
          <inertia>
            <ixx>146.04166666666669</ixx>
            <iyy>146.04166666666669</iyy>
            <izz>10.416666666666666</izz>
            <ixy>0</ixy>
            <ixz>0</ixz>
            <iyz>0</iyz>
          </inertia>
        </inertial>
        <visual name="visual">
          <geometry>
            <box>
              <size>0.25 0.25 1.3 </size>
            </box>
          </geometry>
          <material>
            <ambient>0 0 1 1</ambient>
            <diffuse>0 0 1 1</diffuse>
            <specular>0 0 1 1</specular>
            <emissive>0 0 1 1</emissive>
          </material>
        </visual>
        <collision name="collision">
          <geometry>
            <box>
              <size>0.25 0.25 1.3 </size>
            </box>
          </geometry>
        </collision>
      </link>
      <link name="arm_holder">
        <pose>-0.0675 0 0 0 0 0</pose>
        <inertial>
          <mass>0.1</mass>
          <inertia>
            <ixx>1.6666666666666669e-06</ixx>
            <iyy>0.00015270833333333334</iyy>
            <izz>0.00015270833333333334</izz>
            <ixy>0</ixy>
            <ixz>0</ixz>
            <iyz>0</iyz>
          </inertia>
        </inertial>
        <visual name="visual">
          <geometry>
            <box>
              <size>0.135 0.01 0.01 </size>
            </box>
          </geometry>
          <material>
            <ambient>0 0 1 1</ambient>
            <diffuse>0 0 1 1</diffuse>
            <specular>0 0 1 1</specular>
            <emissive>0 0 1 1</emissive>
          </material>
        </visual>
        <collision name="collision">
          <geometry>
            <box>
              <size>0.135 0.01 0.01 </size>
            </box>
          </geometry>
        </collision>
      </link>
      <link name="arm">
        <pose>-0.145 0.09933466539753061 -0.4900332889206208 0.2 0 0</pose>
        <inertial>
          <mass>0.1</mass>
          <inertia>
            <ixx>0.008355833333333333</ixx>
            <iyy>0.008355833333333333</iyy>
            <izz>4.5e-05</izz>
            <ixy>0</ixy>
            <ixz>0</ixz>
            <iyz>0</iyz>
          </inertia>
        </inertial>
        <visual name="visual">
          <geometry>
            <cylinder>
              <radius>0.03</radius>
              <length>1.0</length>
            </cylinder>
          </geometry>
          <material>
            <ambient>1 0 0 1</ambient>
            <diffuse>1 0 0 1</diffuse>
            <specular>1 0 0 1</specular>
            <emissive>1 0 0 1</emissive>
          </material>
        </visual>
        <collision name="collision">
          <geometry>
            <cylinder>
              <radius>0.03</radius>
              <length>1.0</length>
            </cylinder>
          </geometry>
        </collision>
      </link>
      <link name="bob">
        <pose>-0.145 0.19866933079506122 -0.9800665778412416 0 0 0</pose>
        <inertial>
          <mass>5</mass>
          <inertia>
            <ixx>0.020000000000000004</ixx>
            <iyy>0.020000000000000004</iyy>
            <izz>0.020000000000000004</izz>
            <ixy>0</ixy>
            <ixz>0</ixz>
            <iyz>0</iyz>
          </inertia>
        </inertial>
        <visual name="visual">
          <geometry>
            <sphere>
              <radius>0.1</radius>
            </sphere>
          </geometry>
          <material>
            <ambient>0 1 0 1</ambient>
            <diffuse>0 1 0 1</diffuse>
            <specular>0 1 0 1</specular>
            <emissive>0 1 0 1</emissive>
          </material>
        </visual>
        <collision name="collision">
          <geometry>
            <sphere>
              <radius>0.1</radius>
            </sphere>
          </geometry>
        </collision>
      </link>
      <joint name="arm_joint_2" type="revolute">
        <parent>arm_holder</parent>
        <child>arm</child>
        <pose>0 0 0.5 0 0 0</pose>
        <axis>
          <xyz>1 0 0</xyz>
          <limit>
            <lower>-1e4</lower>
            <upper>1e4</upper>
          </limit>
          <dynamics>
            <damping>5</damping>
            <friction>0.0</friction>
          </dynamics>
        </axis>
      </joint>
      <joint name="arm_holder_joint" type="fixed">
        <parent>base_link</parent>
        <child>arm_holder</child>
      </joint>
      <joint name="bob_joint" type="fixed">
        <parent>arm</parent>
        <child>bob</child>
      </joint>
      <plugin filename="libPID_Pendulum" name="simp_pend_ctrl::PID_Pendulum">
        <joint_name>arm_joint_2</joint_name>
        <p_gain>200.0</p_gain>
        <i_gain>0.5</i_gain>
        <d_gain>50.0</d_gain>
        <target_position>3.14159</target_position>
        <theta_0>0.2</theta_0>
      </plugin>
      <!--
            <plugin filename="libGravity_Invert"
                name="simp_pend_ctrl::Gravity_Invert">
                <joint_name>arm_joint_${n}</joint_name>
                <bob_mass>${bob_mass} </bob_mass>
                <arm_length>${arm_length}</arm_length>
                <theta_0>${theta_0} </theta_0>
                <n>${n}</n>
            </plugin>
            -->
    </model>
    <model name="simple_pendulum_3">
      <pose>6 0 1.31 0 0 0</pose>
      <link name="base_link">
        <pose>0 0 -0.65 0 0 0</pose>
        <inertial>
          <mass>1000</mass>
          <inertia>
            <ixx>146.04166666666669</ixx>
            <iyy>146.04166666666669</iyy>
            <izz>10.416666666666666</izz>
            <ixy>0</ixy>
            <ixz>0</ixz>
            <iyz>0</iyz>
          </inertia>
        </inertial>
        <visual name="visual">
          <geometry>
            <box>
              <size>0.25 0.25 1.3 </size>
            </box>
          </geometry>
          <material>
            <ambient>0 0 1 1</ambient>
            <diffuse>0 0 1 1</diffuse>
            <specular>0 0 1 1</specular>
            <emissive>0 0 1 1</emissive>
          </material>
        </visual>
        <collision name="collision">
          <geometry>
            <box>
              <size>0.25 0.25 1.3 </size>
            </box>
          </geometry>
        </collision>
      </link>
      <link name="arm_holder">
        <pose>-0.0675 0 0 0 0 0</pose>
        <inertial>
          <mass>0.1</mass>
          <inertia>
            <ixx>1.6666666666666669e-06</ixx>
            <iyy>0.00015270833333333334</iyy>
            <izz>0.00015270833333333334</izz>
            <ixy>0</ixy>
            <ixz>0</ixz>
            <iyz>0</iyz>
          </inertia>
        </inertial>
        <visual name="visual">
          <geometry>
            <box>
              <size>0.135 0.01 0.01 </size>
            </box>
          </geometry>
          <material>
            <ambient>0 0 1 1</ambient>
            <diffuse>0 0 1 1</diffuse>
            <specular>0 0 1 1</specular>
            <emissive>0 0 1 1</emissive>
          </material>
        </visual>
        <collision name="collision">
          <geometry>
            <box>
              <size>0.135 0.01 0.01 </size>
            </box>
          </geometry>
        </collision>
      </link>
      <link name="arm">
        <pose>-0.145 0.3377315902755755 0.3686968577706227 2.4 0 0</pose>
        <inertial>
          <mass>0.1</mass>
          <inertia>
            <ixx>0.008355833333333333</ixx>
            <iyy>0.008355833333333333</iyy>
            <izz>4.5e-05</izz>
            <ixy>0</ixy>
            <ixz>0</ixz>
            <iyz>0</iyz>
          </inertia>
        </inertial>
        <visual name="visual">
          <geometry>
            <cylinder>
              <radius>0.03</radius>
              <length>1.0</length>
            </cylinder>
          </geometry>
          <material>
            <ambient>1 0 0 1</ambient>
            <diffuse>1 0 0 1</diffuse>
            <specular>1 0 0 1</specular>
            <emissive>1 0 0 1</emissive>
          </material>
        </visual>
        <collision name="collision">
          <geometry>
            <cylinder>
              <radius>0.03</radius>
              <length>1.0</length>
            </cylinder>
          </geometry>
        </collision>
      </link>
      <link name="bob">
        <pose>-0.145 0.675463180551151 0.7373937155412454 0 0 0</pose>
        <inertial>
          <mass>5</mass>
          <inertia>
            <ixx>0.020000000000000004</ixx>
            <iyy>0.020000000000000004</iyy>
            <izz>0.020000000000000004</izz>
            <ixy>0</ixy>
            <ixz>0</ixz>
            <iyz>0</iyz>
          </inertia>
        </inertial>
        <visual name="visual">
          <geometry>
            <sphere>
              <radius>0.1</radius>
            </sphere>
          </geometry>
          <material>
            <ambient>0 1 0 1</ambient>
            <diffuse>0 1 0 1</diffuse>
            <specular>0 1 0 1</specular>
            <emissive>0 1 0 1</emissive>
          </material>
        </visual>
        <collision name="collision">
          <geometry>
            <sphere>
              <radius>0.1</radius>
            </sphere>
          </geometry>
        </collision>
      </link>
      <joint name="arm_joint_3" type="revolute">
        <parent>arm_holder</parent>
        <child>arm</child>
        <pose>0 0 0.5 0 0 0</pose>
        <axis>
          <xyz>1 0 0</xyz>
          <limit>
            <lower>-1e4</lower>
            <upper>1e4</upper>
          </limit>
          <dynamics>
            <damping>5</damping>
            <friction>0.0</friction>
          </dynamics>
        </axis>
      </joint>
      <joint name="arm_holder_joint" type="fixed">
        <parent>base_link</parent>
        <child>arm_holder</child>
      </joint>
      <joint name="bob_joint" type="fixed">
        <parent>arm</parent>
        <child>bob</child>
      </joint>
      <plugin filename="libPID_Pendulum" name="simp_pend_ctrl::PID_Pendulum">
        <joint_name>arm_joint_3</joint_name>
        <p_gain>200.0</p_gain>
        <i_gain>0.5</i_gain>
        <d_gain>50.0</d_gain>
        <target_position>3.14159</target_position>
        <theta_0>2.4</theta_0>
      </plugin>
      <!--
            <plugin filename="libGravity_Invert"
                name="simp_pend_ctrl::Gravity_Invert">
                <joint_name>arm_joint_${n}</joint_name>
                <bob_mass>${bob_mass} </bob_mass>
                <arm_length>${arm_length}</arm_length>
                <theta_0>${theta_0} </theta_0>
                <n>${n}</n>
            </plugin>
            -->
    </model>
    <model name="simple_pendulum_4">
      <pose>8 0 1.31 0 0 0</pose>
      <link name="base_link">
        <pose>0 0 -0.65 0 0 0</pose>
        <inertial>
          <mass>1000</mass>
          <inertia>
            <ixx>146.04166666666669</ixx>
            <iyy>146.04166666666669</iyy>
            <izz>10.416666666666666</izz>
            <ixy>0</ixy>
            <ixz>0</ixz>
            <iyz>0</iyz>
          </inertia>
        </inertial>
        <visual name="visual">
          <geometry>
            <box>
              <size>0.25 0.25 1.3 </size>
            </box>
          </geometry>
          <material>
            <ambient>0 0 1 1</ambient>
            <diffuse>0 0 1 1</diffuse>
            <specular>0 0 1 1</specular>
            <emissive>0 0 1 1</emissive>
          </material>
        </visual>
        <collision name="collision">
          <geometry>
            <box>
              <size>0.25 0.25 1.3 </size>
            </box>
          </geometry>
        </collision>
      </link>
      <link name="arm_holder">
        <pose>-0.0675 0 0 0 0 0</pose>
        <inertial>
          <mass>0.1</mass>
          <inertia>
            <ixx>1.6666666666666669e-06</ixx>
            <iyy>0.00015270833333333334</iyy>
            <izz>0.00015270833333333334</izz>
            <ixy>0</ixy>
            <ixz>0</ixz>
            <iyz>0</iyz>
          </inertia>
        </inertial>
        <visual name="visual">
          <geometry>
            <box>
              <size>0.135 0.01 0.01 </size>
            </box>
          </geometry>
          <material>
            <ambient>0 0 1 1</ambient>
            <diffuse>0 0 1 1</diffuse>
            <specular>0 0 1 1</specular>
            <emissive>0 0 1 1</emissive>
          </material>
        </visual>
        <collision name="collision">
          <geometry>
            <box>
              <size>0.135 0.01 0.01 </size>
            </box>
          </geometry>
        </collision>
      </link>
      <link name="arm">
        <pose>-0.145 -0.4817790927085965 -0.13374941431229367 -1.3 0 0</pose>
        <inertial>
          <mass>0.1</mass>
          <inertia>
            <ixx>0.008355833333333333</ixx>
            <iyy>0.008355833333333333</iyy>
            <izz>4.5e-05</izz>
            <ixy>0</ixy>
            <ixz>0</ixz>
            <iyz>0</iyz>
          </inertia>
        </inertial>
        <visual name="visual">
          <geometry>
            <cylinder>
              <radius>0.03</radius>
              <length>1.0</length>
            </cylinder>
          </geometry>
          <material>
            <ambient>1 0 0 1</ambient>
            <diffuse>1 0 0 1</diffuse>
            <specular>1 0 0 1</specular>
            <emissive>1 0 0 1</emissive>
          </material>
        </visual>
        <collision name="collision">
          <geometry>
            <cylinder>
              <radius>0.03</radius>
              <length>1.0</length>
            </cylinder>
          </geometry>
        </collision>
      </link>
      <link name="bob">
        <pose>-0.145 -0.963558185417193 -0.26749882862458735 0 0 0</pose>
        <inertial>
          <mass>5</mass>
          <inertia>
            <ixx>0.020000000000000004</ixx>
            <iyy>0.020000000000000004</iyy>
            <izz>0.020000000000000004</izz>
            <ixy>0</ixy>
            <ixz>0</ixz>
            <iyz>0</iyz>
          </inertia>
        </inertial>
        <visual name="visual">
          <geometry>
            <sphere>
              <radius>0.1</radius>
            </sphere>
          </geometry>
          <material>
            <ambient>0 1 0 1</ambient>
            <diffuse>0 1 0 1</diffuse>
            <specular>0 1 0 1</specular>
            <emissive>0 1 0 1</emissive>
          </material>
        </visual>
        <collision name="collision">
          <geometry>
            <sphere>
              <radius>0.1</radius>
            </sphere>
          </geometry>
        </collision>
      </link>
      <joint name="arm_joint_4" type="revolute">
        <parent>arm_holder</parent>
        <child>arm</child>
        <pose>0 0 0.5 0 0 0</pose>
        <axis>
          <xyz>1 0 0</xyz>
          <limit>
            <lower>-1e4</lower>
            <upper>1e4</upper>
          </limit>
          <dynamics>
            <damping>5</damping>
            <friction>0.0</friction>
          </dynamics>
        </axis>
      </joint>
      <joint name="arm_holder_joint" type="fixed">
        <parent>base_link</parent>
        <child>arm_holder</child>
      </joint>
      <joint name="bob_joint" type="fixed">
        <parent>arm</parent>
        <child>bob</child>
      </joint>
      <plugin filename="libPID_Pendulum" name="simp_pend_ctrl::PID_Pendulum">
        <joint_name>arm_joint_4</joint_name>
        <p_gain>200.0</p_gain>
        <i_gain>0.5</i_gain>
        <d_gain>50.0</d_gain>
        <target_position>3.14159</target_position>
        <theta_0>-1.3</theta_0>
      </plugin>
      <!--
            <plugin filename="libGravity_Invert"
                name="simp_pend_ctrl::Gravity_Invert">
                <joint_name>arm_joint_${n}</joint_name>
                <bob_mass>${bob_mass} </bob_mass>
                <arm_length>${arm_length}</arm_length>
                <theta_0>${theta_0} </theta_0>
                <n>${n}</n>
            </plugin>
            -->
    </model>
    <model name="simple_pendulum_10">
      <pose>0 2 1.51 0 0 0</pose>
      <link name="base_link">
        <pose>0 0 -0.75 0 0 0</pose>
        <inertial>
          <mass>1000</mass>
          <inertia>
            <ixx>192.70833333333334</ixx>
            <iyy>192.70833333333334</iyy>
            <izz>10.416666666666666</izz>
            <ixy>0</ixy>
            <ixz>0</ixz>
            <iyz>0</iyz>
          </inertia>
        </inertial>
        <visual name="visual">
          <geometry>
            <box>
              <size>0.25 0.25 1.5 </size>
            </box>
          </geometry>
          <material>
            <ambient>0 0 1 1</ambient>
            <diffuse>0 0 1 1</diffuse>
            <specular>0 0 1 1</specular>
            <emissive>0 0 1 1</emissive>
          </material>
        </visual>
        <collision name="collision">
          <geometry>
            <box>
              <size>0.25 0.25 1.5 </size>
            </box>
          </geometry>
        </collision>
      </link>
      <link name="arm_holder">
        <pose>-0.0675 0 0 0 0 0</pose>
        <inertial>
          <mass>0.1</mass>
          <inertia>
            <ixx>1.6666666666666669e-06</ixx>
            <iyy>0.00015270833333333334</iyy>
            <izz>0.00015270833333333334</izz>
            <ixy>0</ixy>
            <ixz>0</ixz>
            <iyz>0</iyz>
          </inertia>
        </inertial>
        <visual name="visual">
          <geometry>
            <box>
              <size>0.135 0.01 0.01 </size>
            </box>
          </geometry>
          <material>
            <ambient>0 0 1 1</ambient>
            <diffuse>0 0 1 1</diffuse>
            <specular>0 0 1 1</specular>
            <emissive>0 0 1 1</emissive>
          </material>
        </visual>
        <collision name="collision">
          <geometry>
            <box>
              <size>0.135 0.01 0.01 </size>
            </box>
          </geometry>
        </collision>
      </link>
      <link name="arm">
        <pose>-0.145 0.2531219225006229 -0.5986896461018754 0.4 0 0</pose>
        <inertial>
          <mass>0.1</mass>
          <inertia>
            <ixx>0.014105833333333337</ixx>
            <iyy>0.014105833333333337</iyy>
            <izz>4.5e-05</izz>
            <ixy>0</ixy>
            <ixz>0</ixz>
            <iyz>0</iyz>
          </inertia>
        </inertial>
        <visual name="visual">
          <geometry>
            <cylinder>
              <radius>0.03</radius>
              <length>1.3</length>
            </cylinder>
          </geometry>
          <material>
            <ambient>1 0 0 1</ambient>
            <diffuse>1 0 0 1</diffuse>
            <specular>1 0 0 1</specular>
            <emissive>1 0 0 1</emissive>
          </material>
        </visual>
        <collision name="collision">
          <geometry>
            <cylinder>
              <radius>0.03</radius>
              <length>1.3</length>
            </cylinder>
          </geometry>
        </collision>
      </link>
      <link name="bob">
        <pose>-0.145 0.5062438450012458 -1.1973792922037507 0 0 0</pose>
        <inertial>
          <mass>5</mass>
          <inertia>
            <ixx>0.020000000000000004</ixx>
            <iyy>0.020000000000000004</iyy>
            <izz>0.020000000000000004</izz>
            <ixy>0</ixy>
            <ixz>0</ixz>
            <iyz>0</iyz>
          </inertia>
        </inertial>
        <visual name="visual">
          <geometry>
            <sphere>
              <radius>0.1</radius>
            </sphere>
          </geometry>
          <material>
            <ambient>0 1 0 1</ambient>
            <diffuse>0 1 0 1</diffuse>
            <specular>0 1 0 1</specular>
            <emissive>0 1 0 1</emissive>
          </material>
        </visual>
        <collision name="collision">
          <geometry>
            <sphere>
              <radius>0.1</radius>
            </sphere>
          </geometry>
        </collision>
      </link>
      <joint name="arm_joint_10" type="revolute">
        <parent>arm_holder</parent>
        <child>arm</child>
        <pose>0 0 0.65 0 0 0</pose>
        <axis>
          <xyz>1 0 0</xyz>
          <limit>
            <lower>-1e4</lower>
            <upper>1e4</upper>
          </limit>
          <dynamics>
            <damping>5</damping>
            <friction>0.0</friction>
          </dynamics>
        </axis>
      </joint>
      <joint name="arm_holder_joint" type="fixed">
        <parent>base_link</parent>
        <child>arm_holder</child>
      </joint>
      <joint name="bob_joint" type="fixed">
        <parent>arm</parent>
        <child>bob</child>
      </joint>
      <plugin filename="libPID_Pendulum" name="simp_pend_ctrl::PID_Pendulum">
        <joint_name>arm_joint_10</joint_name>
        <p_gain>200.0</p_gain>
        <i_gain>0.5</i_gain>
        <d_gain>50.0</d_gain>
        <target_position>3.14159</target_position>
        <theta_0>0.4</theta_0>
      </plugin>
      <!--
            <plugin filename="libGravity_Invert"
                name="simp_pend_ctrl::Gravity_Invert">
                <joint_name>arm_joint_${n}</joint_name>
                <bob_mass>${bob_mass} </bob_mass>
                <arm_length>${arm_length}</arm_length>
                <theta_0>${theta_0} </theta_0>
                <n>${n}</n>
            </plugin>
            -->
    </model>
    <model name="simple_pendulum_11">
      <pose>2 2 1.51 0 0 0</pose>
      <link name="base_link">
        <pose>0 0 -0.75 0 0 0</pose>
        <inertial>
          <mass>1000</mass>
          <inertia>
            <ixx>192.70833333333334</ixx>
            <iyy>192.70833333333334</iyy>
            <izz>10.416666666666666</izz>
            <ixy>0</ixy>
            <ixz>0</ixz>
            <iyz>0</iyz>
          </inertia>
        </inertial>
        <visual name="visual">
          <geometry>
            <box>
              <size>0.25 0.25 1.5 </size>
            </box>
          </geometry>
          <material>
            <ambient>0 0 1 1</ambient>
            <diffuse>0 0 1 1</diffuse>
            <specular>0 0 1 1</specular>
            <emissive>0 0 1 1</emissive>
          </material>
        </visual>
        <collision name="collision">
          <geometry>
            <box>
              <size>0.25 0.25 1.5 </size>
            </box>
          </geometry>
        </collision>
      </link>
      <link name="arm_holder">
        <pose>-0.0675 0 0 0 0 0</pose>
        <inertial>
          <mass>0.1</mass>
          <inertia>
            <ixx>1.6666666666666669e-06</ixx>
            <iyy>0.00015270833333333334</iyy>
            <izz>0.00015270833333333334</izz>
            <ixy>0</ixy>
            <ixz>0</ixz>
            <iyz>0</iyz>
          </inertia>
        </inertial>
        <visual name="visual">
          <geometry>
            <box>
              <size>0.135 0.01 0.01 </size>
            </box>
          </geometry>
          <material>
            <ambient>0 0 1 1</ambient>
            <diffuse>0 0 1 1</diffuse>
            <specular>0 0 1 1</specular>
            <emissive>0 0 1 1</emissive>
          </material>
        </visual>
        <collision name="collision">
          <geometry>
            <box>
              <size>0.135 0.01 0.01 </size>
            </box>
          </geometry>
        </collision>
      </link>
      <link name="arm">
        <pose>-0.145 -0.367017607706773 -0.536468149691291 -0.6 0 0</pose>
        <inertial>
          <mass>0.1</mass>
          <inertia>
            <ixx>0.014105833333333337</ixx>
            <iyy>0.014105833333333337</iyy>
            <izz>4.5e-05</izz>
            <ixy>0</ixy>
            <ixz>0</ixz>
            <iyz>0</iyz>
          </inertia>
        </inertial>
        <visual name="visual">
          <geometry>
            <cylinder>
              <radius>0.03</radius>
              <length>1.3</length>
            </cylinder>
          </geometry>
          <material>
            <ambient>1 0 0 1</ambient>
            <diffuse>1 0 0 1</diffuse>
            <specular>1 0 0 1</specular>
            <emissive>1 0 0 1</emissive>
          </material>
        </visual>
        <collision name="collision">
          <geometry>
            <cylinder>
              <radius>0.03</radius>
              <length>1.3</length>
            </cylinder>
          </geometry>
        </collision>
      </link>
      <link name="bob">
        <pose>-0.145 -0.734035215413546 -1.072936299382582 0 0 0</pose>
        <inertial>
          <mass>5</mass>
          <inertia>
            <ixx>0.020000000000000004</ixx>
            <iyy>0.020000000000000004</iyy>
            <izz>0.020000000000000004</izz>
            <ixy>0</ixy>
            <ixz>0</ixz>
            <iyz>0</iyz>
          </inertia>
        </inertial>
        <visual name="visual">
          <geometry>
            <sphere>
              <radius>0.1</radius>
            </sphere>
          </geometry>
          <material>
            <ambient>0 1 0 1</ambient>
            <diffuse>0 1 0 1</diffuse>
            <specular>0 1 0 1</specular>
            <emissive>0 1 0 1</emissive>
          </material>
        </visual>
        <collision name="collision">
          <geometry>
            <sphere>
              <radius>0.1</radius>
            </sphere>
          </geometry>
        </collision>
      </link>
      <joint name="arm_joint_11" type="revolute">
        <parent>arm_holder</parent>
        <child>arm</child>
        <pose>0 0 0.65 0 0 0</pose>
        <axis>
          <xyz>1 0 0</xyz>
          <limit>
            <lower>-1e4</lower>
            <upper>1e4</upper>
          </limit>
          <dynamics>
            <damping>5</damping>
            <friction>0.0</friction>
          </dynamics>
        </axis>
      </joint>
      <joint name="arm_holder_joint" type="fixed">
        <parent>base_link</parent>
        <child>arm_holder</child>
      </joint>
      <joint name="bob_joint" type="fixed">
        <parent>arm</parent>
        <child>bob</child>
      </joint>
      <plugin filename="libPID_Pendulum" name="simp_pend_ctrl::PID_Pendulum">
        <joint_name>arm_joint_11</joint_name>
        <p_gain>200.0</p_gain>
        <i_gain>0.5</i_gain>
        <d_gain>50.0</d_gain>
        <target_position>3.14159</target_position>
        <theta_0>-0.6</theta_0>
      </plugin>
      <!--
            <plugin filename="libGravity_Invert"
                name="simp_pend_ctrl::Gravity_Invert">
                <joint_name>arm_joint_${n}</joint_name>
                <bob_mass>${bob_mass} </bob_mass>
                <arm_length>${arm_length}</arm_length>
                <theta_0>${theta_0} </theta_0>
                <n>${n}</n>
            </plugin>
            -->
    </model>
    <model name="simple_pendulum_12">
      <pose>4 2 1.51 0 0 0</pose>
      <link name="base_link">
        <pose>0 0 -0.75 0 0 0</pose>
        <inertial>
          <mass>1000</mass>
          <inertia>
            <ixx>192.70833333333334</ixx>
            <iyy>192.70833333333334</iyy>
            <izz>10.416666666666666</izz>
            <ixy>0</ixy>
            <ixz>0</ixz>
            <iyz>0</iyz>
          </inertia>
        </inertial>
        <visual name="visual">
          <geometry>
            <box>
              <size>0.25 0.25 1.5 </size>
            </box>
          </geometry>
          <material>
            <ambient>0 0 1 1</ambient>
            <diffuse>0 0 1 1</diffuse>
            <specular>0 0 1 1</specular>
            <emissive>0 0 1 1</emissive>
          </material>
        </visual>
        <collision name="collision">
          <geometry>
            <box>
              <size>0.25 0.25 1.5 </size>
            </box>
          </geometry>
        </collision>
      </link>
      <link name="arm_holder">
        <pose>-0.0675 0 0 0 0 0</pose>
        <inertial>
          <mass>0.1</mass>
          <inertia>
            <ixx>1.6666666666666669e-06</ixx>
            <iyy>0.00015270833333333334</iyy>
            <izz>0.00015270833333333334</izz>
            <ixy>0</ixy>
            <ixz>0</ixz>
            <iyz>0</iyz>
          </inertia>
        </inertial>
        <visual name="visual">
          <geometry>
            <box>
              <size>0.135 0.01 0.01 </size>
            </box>
          </geometry>
          <material>
            <ambient>0 0 1 1</ambient>
            <diffuse>0 0 1 1</diffuse>
            <specular>0 0 1 1</specular>
            <emissive>0 0 1 1</emissive>
          </material>
        </visual>
        <collision name="collision">
          <geometry>
            <box>
              <size>0.135 0.01 0.01 </size>
            </box>
          </geometry>
        </collision>
      </link>
      <link name="arm">
        <pose>-0.145 0.12913506501678979 -0.6370432755968071 0.2 0 0</pose>
        <inertial>
          <mass>0.1</mass>
          <inertia>
            <ixx>0.014105833333333337</ixx>
            <iyy>0.014105833333333337</iyy>
            <izz>4.5e-05</izz>
            <ixy>0</ixy>
            <ixz>0</ixz>
            <iyz>0</iyz>
          </inertia>
        </inertial>
        <visual name="visual">
          <geometry>
            <cylinder>
              <radius>0.03</radius>
              <length>1.3</length>
            </cylinder>
          </geometry>
          <material>
            <ambient>1 0 0 1</ambient>
            <diffuse>1 0 0 1</diffuse>
            <specular>1 0 0 1</specular>
            <emissive>1 0 0 1</emissive>
          </material>
        </visual>
        <collision name="collision">
          <geometry>
            <cylinder>
              <radius>0.03</radius>
              <length>1.3</length>
            </cylinder>
          </geometry>
        </collision>
      </link>
      <link name="bob">
        <pose>-0.145 0.25827013003357957 -1.2740865511936141 0 0 0</pose>
        <inertial>
          <mass>5</mass>
          <inertia>
            <ixx>0.020000000000000004</ixx>
            <iyy>0.020000000000000004</iyy>
            <izz>0.020000000000000004</izz>
            <ixy>0</ixy>
            <ixz>0</ixz>
            <iyz>0</iyz>
          </inertia>
        </inertial>
        <visual name="visual">
          <geometry>
            <sphere>
              <radius>0.1</radius>
            </sphere>
          </geometry>
          <material>
            <ambient>0 1 0 1</ambient>
            <diffuse>0 1 0 1</diffuse>
            <specular>0 1 0 1</specular>
            <emissive>0 1 0 1</emissive>
          </material>
        </visual>
        <collision name="collision">
          <geometry>
            <sphere>
              <radius>0.1</radius>
            </sphere>
          </geometry>
        </collision>
      </link>
      <joint name="arm_joint_12" type="revolute">
        <parent>arm_holder</parent>
        <child>arm</child>
        <pose>0 0 0.65 0 0 0</pose>
        <axis>
          <xyz>1 0 0</xyz>
          <limit>
            <lower>-1e4</lower>
            <upper>1e4</upper>
          </limit>
          <dynamics>
            <damping>5</damping>
            <friction>0.0</friction>
          </dynamics>
        </axis>
      </joint>
      <joint name="arm_holder_joint" type="fixed">
        <parent>base_link</parent>
        <child>arm_holder</child>
      </joint>
      <joint name="bob_joint" type="fixed">
        <parent>arm</parent>
        <child>bob</child>
      </joint>
      <plugin filename="libPID_Pendulum" name="simp_pend_ctrl::PID_Pendulum">
        <joint_name>arm_joint_12</joint_name>
        <p_gain>200.0</p_gain>
        <i_gain>0.5</i_gain>
        <d_gain>50.0</d_gain>
        <target_position>3.14159</target_position>
        <theta_0>0.2</theta_0>
      </plugin>
      <!--
            <plugin filename="libGravity_Invert"
                name="simp_pend_ctrl::Gravity_Invert">
                <joint_name>arm_joint_${n}</joint_name>
                <bob_mass>${bob_mass} </bob_mass>
                <arm_length>${arm_length}</arm_length>
                <theta_0>${theta_0} </theta_0>
                <n>${n}</n>
            </plugin>
            -->
    </model>
    <model name="simple_pendulum_13">
      <pose>6 2 1.51 0 0 0</pose>
      <link name="base_link">
        <pose>0 0 -0.75 0 0 0</pose>
        <inertial>
          <mass>1000</mass>
          <inertia>
            <ixx>192.70833333333334</ixx>
            <iyy>192.70833333333334</iyy>
            <izz>10.416666666666666</izz>
            <ixy>0</ixy>
            <ixz>0</ixz>
            <iyz>0</iyz>
          </inertia>
        </inertial>
        <visual name="visual">
          <geometry>
            <box>
              <size>0.25 0.25 1.5 </size>
            </box>
          </geometry>
          <material>
            <ambient>0 0 1 1</ambient>
            <diffuse>0 0 1 1</diffuse>
            <specular>0 0 1 1</specular>
            <emissive>0 0 1 1</emissive>
          </material>
        </visual>
        <collision name="collision">
          <geometry>
            <box>
              <size>0.25 0.25 1.5 </size>
            </box>
          </geometry>
        </collision>
      </link>
      <link name="arm_holder">
        <pose>-0.0675 0 0 0 0 0</pose>
        <inertial>
          <mass>0.1</mass>
          <inertia>
            <ixx>1.6666666666666669e-06</ixx>
            <iyy>0.00015270833333333334</iyy>
            <izz>0.00015270833333333334</izz>
            <ixy>0</ixy>
            <ixz>0</ixz>
            <iyz>0</iyz>
          </inertia>
        </inertial>
        <visual name="visual">
          <geometry>
            <box>
              <size>0.135 0.01 0.01 </size>
            </box>
          </geometry>
          <material>
            <ambient>0 0 1 1</ambient>
            <diffuse>0 0 1 1</diffuse>
            <specular>0 0 1 1</specular>
            <emissive>0 0 1 1</emissive>
          </material>
        </visual>
        <collision name="collision">
          <geometry>
            <box>
              <size>0.135 0.01 0.01 </size>
            </box>
          </geometry>
        </collision>
      </link>
      <link name="arm">
        <pose>-0.145 0.4390510673582481 0.47930591510180953 2.4 0 0</pose>
        <inertial>
          <mass>0.1</mass>
          <inertia>
            <ixx>0.014105833333333337</ixx>
            <iyy>0.014105833333333337</iyy>
            <izz>4.5e-05</izz>
            <ixy>0</ixy>
            <ixz>0</ixz>
            <iyz>0</iyz>
          </inertia>
        </inertial>
        <visual name="visual">
          <geometry>
            <cylinder>
              <radius>0.03</radius>
              <length>1.3</length>
            </cylinder>
          </geometry>
          <material>
            <ambient>1 0 0 1</ambient>
            <diffuse>1 0 0 1</diffuse>
            <specular>1 0 0 1</specular>
            <emissive>1 0 0 1</emissive>
          </material>
        </visual>
        <collision name="collision">
          <geometry>
            <cylinder>
              <radius>0.03</radius>
              <length>1.3</length>
            </cylinder>
          </geometry>
        </collision>
      </link>
      <link name="bob">
        <pose>-0.145 0.8781021347164962 0.9586118302036191 0 0 0</pose>
        <inertial>
          <mass>5</mass>
          <inertia>
            <ixx>0.020000000000000004</ixx>
            <iyy>0.020000000000000004</iyy>
            <izz>0.020000000000000004</izz>
            <ixy>0</ixy>
            <ixz>0</ixz>
            <iyz>0</iyz>
          </inertia>
        </inertial>
        <visual name="visual">
          <geometry>
            <sphere>
              <radius>0.1</radius>
            </sphere>
          </geometry>
          <material>
            <ambient>0 1 0 1</ambient>
            <diffuse>0 1 0 1</diffuse>
            <specular>0 1 0 1</specular>
            <emissive>0 1 0 1</emissive>
          </material>
        </visual>
        <collision name="collision">
          <geometry>
            <sphere>
              <radius>0.1</radius>
            </sphere>
          </geometry>
        </collision>
      </link>
      <joint name="arm_joint_13" type="revolute">
        <parent>arm_holder</parent>
        <child>arm</child>
        <pose>0 0 0.65 0 0 0</pose>
        <axis>
          <xyz>1 0 0</xyz>
          <limit>
            <lower>-1e4</lower>
            <upper>1e4</upper>
          </limit>
          <dynamics>
            <damping>5</damping>
            <friction>0.0</friction>
          </dynamics>
        </axis>
      </joint>
      <joint name="arm_holder_joint" type="fixed">
        <parent>base_link</parent>
        <child>arm_holder</child>
      </joint>
      <joint name="bob_joint" type="fixed">
        <parent>arm</parent>
        <child>bob</child>
      </joint>
      <plugin filename="libPID_Pendulum" name="simp_pend_ctrl::PID_Pendulum">
        <joint_name>arm_joint_13</joint_name>
        <p_gain>200.0</p_gain>
        <i_gain>0.5</i_gain>
        <d_gain>50.0</d_gain>
        <target_position>3.14159</target_position>
        <theta_0>2.4</theta_0>
      </plugin>
      <!--
            <plugin filename="libGravity_Invert"
                name="simp_pend_ctrl::Gravity_Invert">
                <joint_name>arm_joint_${n}</joint_name>
                <bob_mass>${bob_mass} </bob_mass>
                <arm_length>${arm_length}</arm_length>
                <theta_0>${theta_0} </theta_0>
                <n>${n}</n>
            </plugin>
            -->
    </model>
    <model name="simple_pendulum_14">
      <pose>8 2 1.51 0 0 0</pose>
      <link name="base_link">
        <pose>0 0 -0.75 0 0 0</pose>
        <inertial>
          <mass>1000</mass>
          <inertia>
            <ixx>192.70833333333334</ixx>
            <iyy>192.70833333333334</iyy>
            <izz>10.416666666666666</izz>
            <ixy>0</ixy>
            <ixz>0</ixz>
            <iyz>0</iyz>
          </inertia>
        </inertial>
        <visual name="visual">
          <geometry>
            <box>
              <size>0.25 0.25 1.5 </size>
            </box>
          </geometry>
          <material>
            <ambient>0 0 1 1</ambient>
            <diffuse>0 0 1 1</diffuse>
            <specular>0 0 1 1</specular>
            <emissive>0 0 1 1</emissive>
          </material>
        </visual>
        <collision name="collision">
          <geometry>
            <box>
              <size>0.25 0.25 1.5 </size>
            </box>
          </geometry>
        </collision>
      </link>
      <link name="arm_holder">
        <pose>-0.0675 0 0 0 0 0</pose>
        <inertial>
          <mass>0.1</mass>
          <inertia>
            <ixx>1.6666666666666669e-06</ixx>
            <iyy>0.00015270833333333334</iyy>
            <izz>0.00015270833333333334</izz>
            <ixy>0</ixy>
            <ixz>0</ixz>
            <iyz>0</iyz>
          </inertia>
        </inertial>
        <visual name="visual">
          <geometry>
            <box>
              <size>0.135 0.01 0.01 </size>
            </box>
          </geometry>
          <material>
            <ambient>0 0 1 1</ambient>
            <diffuse>0 0 1 1</diffuse>
            <specular>0 0 1 1</specular>
            <emissive>0 0 1 1</emissive>
          </material>
        </visual>
        <collision name="collision">
          <geometry>
            <box>
              <size>0.135 0.01 0.01 </size>
            </box>
          </geometry>
        </collision>
      </link>
      <link name="arm">
        <pose>-0.145 -0.6263128205211754 -0.17387423860598178 -1.3 0 0</pose>
        <inertial>
          <mass>0.1</mass>
          <inertia>
            <ixx>0.014105833333333337</ixx>
            <iyy>0.014105833333333337</iyy>
            <izz>4.5e-05</izz>
            <ixy>0</ixy>
            <ixz>0</ixz>
            <iyz>0</iyz>
          </inertia>
        </inertial>
        <visual name="visual">
          <geometry>
            <cylinder>
              <radius>0.03</radius>
              <length>1.3</length>
            </cylinder>
          </geometry>
          <material>
            <ambient>1 0 0 1</ambient>
            <diffuse>1 0 0 1</diffuse>
            <specular>1 0 0 1</specular>
            <emissive>1 0 0 1</emissive>
          </material>
        </visual>
        <collision name="collision">
          <geometry>
            <cylinder>
              <radius>0.03</radius>
              <length>1.3</length>
            </cylinder>
          </geometry>
        </collision>
      </link>
      <link name="bob">
        <pose>-0.145 -1.2526256410423509 -0.34774847721196356 0 0 0</pose>
        <inertial>
          <mass>5</mass>
          <inertia>
            <ixx>0.020000000000000004</ixx>
            <iyy>0.020000000000000004</iyy>
            <izz>0.020000000000000004</izz>
            <ixy>0</ixy>
            <ixz>0</ixz>
            <iyz>0</iyz>
          </inertia>
        </inertial>
        <visual name="visual">
          <geometry>
            <sphere>
              <radius>0.1</radius>
            </sphere>
          </geometry>
          <material>
            <ambient>0 1 0 1</ambient>
            <diffuse>0 1 0 1</diffuse>
            <specular>0 1 0 1</specular>
            <emissive>0 1 0 1</emissive>
          </material>
        </visual>
        <collision name="collision">
          <geometry>
            <sphere>
              <radius>0.1</radius>
            </sphere>
          </geometry>
        </collision>
      </link>
      <joint name="arm_joint_14" type="revolute">
        <parent>arm_holder</parent>
        <child>arm</child>
        <pose>0 0 0.65 0 0 0</pose>
        <axis>
          <xyz>1 0 0</xyz>
          <limit>
            <lower>-1e4</lower>
            <upper>1e4</upper>
          </limit>
          <dynamics>
            <damping>5</damping>
            <friction>0.0</friction>
          </dynamics>
        </axis>
      </joint>
      <joint name="arm_holder_joint" type="fixed">
        <parent>base_link</parent>
        <child>arm_holder</child>
      </joint>
      <joint name="bob_joint" type="fixed">
        <parent>arm</parent>
        <child>bob</child>
      </joint>
      <plugin filename="libPID_Pendulum" name="simp_pend_ctrl::PID_Pendulum">
        <joint_name>arm_joint_14</joint_name>
        <p_gain>200.0</p_gain>
        <i_gain>0.5</i_gain>
        <d_gain>50.0</d_gain>
        <target_position>3.14159</target_position>
        <theta_0>-1.3</theta_0>
      </plugin>
      <!--
            <plugin filename="libGravity_Invert"
                name="simp_pend_ctrl::Gravity_Invert">
                <joint_name>arm_joint_${n}</joint_name>
                <bob_mass>${bob_mass} </bob_mass>
                <arm_length>${arm_length}</arm_length>
                <theta_0>${theta_0} </theta_0>
                <n>${n}</n>
            </plugin>
            -->
    </model>
    <model name="simple_pendulum_20">
      <pose>0 -2 0.76 0 0 0</pose>
      <link name="base_link">
        <pose>0 0 -0.375 0 0 0</pose>
        <inertial>
          <mass>1000</mass>
          <inertia>
            <ixx>52.083333333333336</ixx>
            <iyy>52.083333333333336</iyy>
            <izz>10.416666666666666</izz>
            <ixy>0</ixy>
            <ixz>0</ixz>
            <iyz>0</iyz>
          </inertia>
        </inertial>
        <visual name="visual">
          <geometry>
            <box>
              <size>0.25 0.25 0.75 </size>
            </box>
          </geometry>
          <material>
            <ambient>0 0 1 1</ambient>
            <diffuse>0 0 1 1</diffuse>
            <specular>0 0 1 1</specular>
            <emissive>0 0 1 1</emissive>
          </material>
        </visual>
        <collision name="collision">
          <geometry>
            <box>
              <size>0.25 0.25 0.75 </size>
            </box>
          </geometry>
        </collision>
      </link>
      <link name="arm_holder">
        <pose>-0.0675 0 0 0 0 0</pose>
        <inertial>
          <mass>0.1</mass>
          <inertia>
            <ixx>1.6666666666666669e-06</ixx>
            <iyy>0.00015270833333333334</iyy>
            <izz>0.00015270833333333334</izz>
            <ixy>0</ixy>
            <ixz>0</ixz>
            <iyz>0</iyz>
          </inertia>
        </inertial>
        <visual name="visual">
          <geometry>
            <box>
              <size>0.135 0.01 0.01 </size>
            </box>
          </geometry>
          <material>
            <ambient>0 0 1 1</ambient>
            <diffuse>0 0 1 1</diffuse>
            <specular>0 0 1 1</specular>
            <emissive>0 0 1 1</emissive>
          </material>
        </visual>
        <collision name="collision">
          <geometry>
            <box>
              <size>0.135 0.01 0.01 </size>
            </box>
          </geometry>
        </collision>
      </link>
      <link name="arm">
        <pose>-0.145 0.11682550269259515 -0.2763182982008655 0.4 0 0</pose>
        <inertial>
          <mass>0.1</mass>
          <inertia>
            <ixx>0.0030224999999999996</ixx>
            <iyy>0.0030224999999999996</iyy>
            <izz>4.5e-05</izz>
            <ixy>0</ixy>
            <ixz>0</ixz>
            <iyz>0</iyz>
          </inertia>
        </inertial>
        <visual name="visual">
          <geometry>
            <cylinder>
              <radius>0.03</radius>
              <length>0.6</length>
            </cylinder>
          </geometry>
          <material>
            <ambient>1 0 0 1</ambient>
            <diffuse>1 0 0 1</diffuse>
            <specular>1 0 0 1</specular>
            <emissive>1 0 0 1</emissive>
          </material>
        </visual>
        <collision name="collision">
          <geometry>
            <cylinder>
              <radius>0.03</radius>
              <length>0.6</length>
            </cylinder>
          </geometry>
        </collision>
      </link>
      <link name="bob">
        <pose>-0.145 0.2336510053851903 -0.552636596401731 0 0 0</pose>
        <inertial>
          <mass>5</mass>
          <inertia>
            <ixx>0.020000000000000004</ixx>
            <iyy>0.020000000000000004</iyy>
            <izz>0.020000000000000004</izz>
            <ixy>0</ixy>
            <ixz>0</ixz>
            <iyz>0</iyz>
          </inertia>
        </inertial>
        <visual name="visual">
          <geometry>
            <sphere>
              <radius>0.1</radius>
            </sphere>
          </geometry>
          <material>
            <ambient>0 1 0 1</ambient>
            <diffuse>0 1 0 1</diffuse>
            <specular>0 1 0 1</specular>
            <emissive>0 1 0 1</emissive>
          </material>
        </visual>
        <collision name="collision">
          <geometry>
            <sphere>
              <radius>0.1</radius>
            </sphere>
          </geometry>
        </collision>
      </link>
      <joint name="arm_joint_20" type="revolute">
        <parent>arm_holder</parent>
        <child>arm</child>
        <pose>0 0 0.3 0 0 0</pose>
        <axis>
          <xyz>1 0 0</xyz>
          <limit>
            <lower>-1e4</lower>
            <upper>1e4</upper>
          </limit>
          <dynamics>
            <damping>5</damping>
            <friction>0.0</friction>
          </dynamics>
        </axis>
      </joint>
      <joint name="arm_holder_joint" type="fixed">
        <parent>base_link</parent>
        <child>arm_holder</child>
      </joint>
      <joint name="bob_joint" type="fixed">
        <parent>arm</parent>
        <child>bob</child>
      </joint>
      <plugin filename="libPID_Pendulum" name="simp_pend_ctrl::PID_Pendulum">
        <joint_name>arm_joint_20</joint_name>
        <p_gain>200.0</p_gain>
        <i_gain>0.5</i_gain>
        <d_gain>50.0</d_gain>
        <target_position>3.14159</target_position>
        <theta_0>0.4</theta_0>
      </plugin>
      <!--
            <plugin filename="libGravity_Invert"
                name="simp_pend_ctrl::Gravity_Invert">
                <joint_name>arm_joint_${n}</joint_name>
                <bob_mass>${bob_mass} </bob_mass>
                <arm_length>${arm_length}</arm_length>
                <theta_0>${theta_0} </theta_0>
                <n>${n}</n>
            </plugin>
            -->
    </model>
    <model name="simple_pendulum_21">
      <pose>2 -2 0.76 0 0 0</pose>
      <link name="base_link">
        <pose>0 0 -0.375 0 0 0</pose>
        <inertial>
          <mass>1000</mass>
          <inertia>
            <ixx>52.083333333333336</ixx>
            <iyy>52.083333333333336</iyy>
            <izz>10.416666666666666</izz>
            <ixy>0</ixy>
            <ixz>0</ixz>
            <iyz>0</iyz>
          </inertia>
        </inertial>
        <visual name="visual">
          <geometry>
            <box>
              <size>0.25 0.25 0.75 </size>
            </box>
          </geometry>
          <material>
            <ambient>0 0 1 1</ambient>
            <diffuse>0 0 1 1</diffuse>
            <specular>0 0 1 1</specular>
            <emissive>0 0 1 1</emissive>
          </material>
        </visual>
        <collision name="collision">
          <geometry>
            <box>
              <size>0.25 0.25 0.75 </size>
            </box>
          </geometry>
        </collision>
      </link>
      <link name="arm_holder">
        <pose>-0.0675 0 0 0 0 0</pose>
        <inertial>
          <mass>0.1</mass>
          <inertia>
            <ixx>1.6666666666666669e-06</ixx>
            <iyy>0.00015270833333333334</iyy>
            <izz>0.00015270833333333334</izz>
            <ixy>0</ixy>
            <ixz>0</ixz>
            <iyz>0</iyz>
          </inertia>
        </inertial>
        <visual name="visual">
          <geometry>
            <box>
              <size>0.135 0.01 0.01 </size>
            </box>
          </geometry>
          <material>
            <ambient>0 0 1 1</ambient>
            <diffuse>0 0 1 1</diffuse>
            <specular>0 0 1 1</specular>
            <emissive>0 0 1 1</emissive>
          </material>
        </visual>
        <collision name="collision">
          <geometry>
            <box>
              <size>0.135 0.01 0.01 </size>
            </box>
          </geometry>
        </collision>
      </link>
      <link name="arm">
        <pose>-0.145 -0.1693927420185106 -0.24760068447290348 -0.6 0 0</pose>
        <inertial>
          <mass>0.1</mass>
          <inertia>
            <ixx>0.0030224999999999996</ixx>
            <iyy>0.0030224999999999996</iyy>
            <izz>4.5e-05</izz>
            <ixy>0</ixy>
            <ixz>0</ixz>
            <iyz>0</iyz>
          </inertia>
        </inertial>
        <visual name="visual">
          <geometry>
            <cylinder>
              <radius>0.03</radius>
              <length>0.6</length>
            </cylinder>
          </geometry>
          <material>
            <ambient>1 0 0 1</ambient>
            <diffuse>1 0 0 1</diffuse>
            <specular>1 0 0 1</specular>
            <emissive>1 0 0 1</emissive>
          </material>
        </visual>
        <collision name="collision">
          <geometry>
            <cylinder>
              <radius>0.03</radius>
              <length>0.6</length>
            </cylinder>
          </geometry>
        </collision>
      </link>
      <link name="bob">
        <pose>-0.145 -0.3387854840370212 -0.49520136894580696 0 0 0</pose>
        <inertial>
          <mass>5</mass>
          <inertia>
            <ixx>0.020000000000000004</ixx>
            <iyy>0.020000000000000004</iyy>
            <izz>0.020000000000000004</izz>
            <ixy>0</ixy>
            <ixz>0</ixz>
            <iyz>0</iyz>
          </inertia>
        </inertial>
        <visual name="visual">
          <geometry>
            <sphere>
              <radius>0.1</radius>
            </sphere>
          </geometry>
          <material>
            <ambient>0 1 0 1</ambient>
            <diffuse>0 1 0 1</diffuse>
            <specular>0 1 0 1</specular>
            <emissive>0 1 0 1</emissive>
          </material>
        </visual>
        <collision name="collision">
          <geometry>
            <sphere>
              <radius>0.1</radius>
            </sphere>
          </geometry>
        </collision>
      </link>
      <joint name="arm_joint_21" type="revolute">
        <parent>arm_holder</parent>
        <child>arm</child>
        <pose>0 0 0.3 0 0 0</pose>
        <axis>
          <xyz>1 0 0</xyz>
          <limit>
            <lower>-1e4</lower>
            <upper>1e4</upper>
          </limit>
          <dynamics>
            <damping>5</damping>
            <friction>0.0</friction>
          </dynamics>
        </axis>
      </joint>
      <joint name="arm_holder_joint" type="fixed">
        <parent>base_link</parent>
        <child>arm_holder</child>
      </joint>
      <joint name="bob_joint" type="fixed">
        <parent>arm</parent>
        <child>bob</child>
      </joint>
      <plugin filename="libPID_Pendulum" name="simp_pend_ctrl::PID_Pendulum">
        <joint_name>arm_joint_21</joint_name>
        <p_gain>200.0</p_gain>
        <i_gain>0.5</i_gain>
        <d_gain>50.0</d_gain>
        <target_position>3.14159</target_position>
        <theta_0>-0.6</theta_0>
      </plugin>
      <!--
            <plugin filename="libGravity_Invert"
                name="simp_pend_ctrl::Gravity_Invert">
                <joint_name>arm_joint_${n}</joint_name>
                <bob_mass>${bob_mass} </bob_mass>
                <arm_length>${arm_length}</arm_length>
                <theta_0>${theta_0} </theta_0>
                <n>${n}</n>
            </plugin>
            -->
    </model>
    <model name="simple_pendulum_22">
      <pose>4 -2 0.76 0 0 0</pose>
      <link name="base_link">
        <pose>0 0 -0.375 0 0 0</pose>
        <inertial>
          <mass>1000</mass>
          <inertia>
            <ixx>52.083333333333336</ixx>
            <iyy>52.083333333333336</iyy>
            <izz>10.416666666666666</izz>
            <ixy>0</ixy>
            <ixz>0</ixz>
            <iyz>0</iyz>
          </inertia>
        </inertial>
        <visual name="visual">
          <geometry>
            <box>
              <size>0.25 0.25 0.75 </size>
            </box>
          </geometry>
          <material>
            <ambient>0 0 1 1</ambient>
            <diffuse>0 0 1 1</diffuse>
            <specular>0 0 1 1</specular>
            <emissive>0 0 1 1</emissive>
          </material>
        </visual>
        <collision name="collision">
          <geometry>
            <box>
              <size>0.25 0.25 0.75 </size>
            </box>
          </geometry>
        </collision>
      </link>
      <link name="arm_holder">
        <pose>-0.0675 0 0 0 0 0</pose>
        <inertial>
          <mass>0.1</mass>
          <inertia>
            <ixx>1.6666666666666669e-06</ixx>
            <iyy>0.00015270833333333334</iyy>
            <izz>0.00015270833333333334</izz>
            <ixy>0</ixy>
            <ixz>0</ixz>
            <iyz>0</iyz>
          </inertia>
        </inertial>
        <visual name="visual">
          <geometry>
            <box>
              <size>0.135 0.01 0.01 </size>
            </box>
          </geometry>
          <material>
            <ambient>0 0 1 1</ambient>
            <diffuse>0 0 1 1</diffuse>
            <specular>0 0 1 1</specular>
            <emissive>0 0 1 1</emissive>
          </material>
        </visual>
        <collision name="collision">
          <geometry>
            <box>
              <size>0.135 0.01 0.01 </size>
            </box>
          </geometry>
        </collision>
      </link>
      <link name="arm">
        <pose>-0.145 0.05960079923851836 -0.29401997335237245 0.2 0 0</pose>
        <inertial>
          <mass>0.1</mass>
          <inertia>
            <ixx>0.0030224999999999996</ixx>
            <iyy>0.0030224999999999996</iyy>
            <izz>4.5e-05</izz>
            <ixy>0</ixy>
            <ixz>0</ixz>
            <iyz>0</iyz>
          </inertia>
        </inertial>
        <visual name="visual">
          <geometry>
            <cylinder>
              <radius>0.03</radius>
              <length>0.6</length>
            </cylinder>
          </geometry>
          <material>
            <ambient>1 0 0 1</ambient>
            <diffuse>1 0 0 1</diffuse>
            <specular>1 0 0 1</specular>
            <emissive>1 0 0 1</emissive>
          </material>
        </visual>
        <collision name="collision">
          <geometry>
            <cylinder>
              <radius>0.03</radius>
              <length>0.6</length>
            </cylinder>
          </geometry>
        </collision>
      </link>
      <link name="bob">
        <pose>-0.145 0.11920159847703672 -0.5880399467047449 0 0 0</pose>
        <inertial>
          <mass>5</mass>
          <inertia>
            <ixx>0.020000000000000004</ixx>
            <iyy>0.020000000000000004</iyy>
            <izz>0.020000000000000004</izz>
            <ixy>0</ixy>
            <ixz>0</ixz>
            <iyz>0</iyz>
          </inertia>
        </inertial>
        <visual name="visual">
          <geometry>
            <sphere>
              <radius>0.1</radius>
            </sphere>
          </geometry>
          <material>
            <ambient>0 1 0 1</ambient>
            <diffuse>0 1 0 1</diffuse>
            <specular>0 1 0 1</specular>
            <emissive>0 1 0 1</emissive>
          </material>
        </visual>
        <collision name="collision">
          <geometry>
            <sphere>
              <radius>0.1</radius>
            </sphere>
          </geometry>
        </collision>
      </link>
      <joint name="arm_joint_22" type="revolute">
        <parent>arm_holder</parent>
        <child>arm</child>
        <pose>0 0 0.3 0 0 0</pose>
        <axis>
          <xyz>1 0 0</xyz>
          <limit>
            <lower>-1e4</lower>
            <upper>1e4</upper>
          </limit>
          <dynamics>
            <damping>5</damping>
            <friction>0.0</friction>
          </dynamics>
        </axis>
      </joint>
      <joint name="arm_holder_joint" type="fixed">
        <parent>base_link</parent>
        <child>arm_holder</child>
      </joint>
      <joint name="bob_joint" type="fixed">
        <parent>arm</parent>
        <child>bob</child>
      </joint>
      <plugin filename="libPID_Pendulum" name="simp_pend_ctrl::PID_Pendulum">
        <joint_name>arm_joint_22</joint_name>
        <p_gain>200.0</p_gain>
        <i_gain>0.5</i_gain>
        <d_gain>50.0</d_gain>
        <target_position>3.14159</target_position>
        <theta_0>0.2</theta_0>
      </plugin>
      <!--
            <plugin filename="libGravity_Invert"
                name="simp_pend_ctrl::Gravity_Invert">
                <joint_name>arm_joint_${n}</joint_name>
                <bob_mass>${bob_mass} </bob_mass>
                <arm_length>${arm_length}</arm_length>
                <theta_0>${theta_0} </theta_0>
                <n>${n}</n>
            </plugin>
            -->
    </model>
    <model name="simple_pendulum_23">
      <pose>6 -2 0.76 0 0 0</pose>
      <link name="base_link">
        <pose>0 0 -0.375 0 0 0</pose>
        <inertial>
          <mass>1000</mass>
          <inertia>
            <ixx>52.083333333333336</ixx>
            <iyy>52.083333333333336</iyy>
            <izz>10.416666666666666</izz>
            <ixy>0</ixy>
            <ixz>0</ixz>
            <iyz>0</iyz>
          </inertia>
        </inertial>
        <visual name="visual">
          <geometry>
            <box>
              <size>0.25 0.25 0.75 </size>
            </box>
          </geometry>
          <material>
            <ambient>0 0 1 1</ambient>
            <diffuse>0 0 1 1</diffuse>
            <specular>0 0 1 1</specular>
            <emissive>0 0 1 1</emissive>
          </material>
        </visual>
        <collision name="collision">
          <geometry>
            <box>
              <size>0.25 0.25 0.75 </size>
            </box>
          </geometry>
        </collision>
      </link>
      <link name="arm_holder">
        <pose>-0.0675 0 0 0 0 0</pose>
        <inertial>
          <mass>0.1</mass>
          <inertia>
            <ixx>1.6666666666666669e-06</ixx>
            <iyy>0.00015270833333333334</iyy>
            <izz>0.00015270833333333334</izz>
            <ixy>0</ixy>
            <ixz>0</ixz>
            <iyz>0</iyz>
          </inertia>
        </inertial>
        <visual name="visual">
          <geometry>
            <box>
              <size>0.135 0.01 0.01 </size>
            </box>
          </geometry>
          <material>
            <ambient>0 0 1 1</ambient>
            <diffuse>0 0 1 1</diffuse>
            <specular>0 0 1 1</specular>
            <emissive>0 0 1 1</emissive>
          </material>
        </visual>
        <collision name="collision">
          <geometry>
            <box>
              <size>0.135 0.01 0.01 </size>
            </box>
          </geometry>
        </collision>
      </link>
      <link name="arm">
        <pose>-0.145 0.20263895416534528 0.22121811466237362 2.4 0 0</pose>
        <inertial>
          <mass>0.1</mass>
          <inertia>
            <ixx>0.0030224999999999996</ixx>
            <iyy>0.0030224999999999996</iyy>
            <izz>4.5e-05</izz>
            <ixy>0</ixy>
            <ixz>0</ixz>
            <iyz>0</iyz>
          </inertia>
        </inertial>
        <visual name="visual">
          <geometry>
            <cylinder>
              <radius>0.03</radius>
              <length>0.6</length>
            </cylinder>
          </geometry>
          <material>
            <ambient>1 0 0 1</ambient>
            <diffuse>1 0 0 1</diffuse>
            <specular>1 0 0 1</specular>
            <emissive>1 0 0 1</emissive>
          </material>
        </visual>
        <collision name="collision">
          <geometry>
            <cylinder>
              <radius>0.03</radius>
              <length>0.6</length>
            </cylinder>
          </geometry>
        </collision>
      </link>
      <link name="bob">
        <pose>-0.145 0.40527790833069055 0.44243622932474724 0 0 0</pose>
        <inertial>
          <mass>5</mass>
          <inertia>
            <ixx>0.020000000000000004</ixx>
            <iyy>0.020000000000000004</iyy>
            <izz>0.020000000000000004</izz>
            <ixy>0</ixy>
            <ixz>0</ixz>
            <iyz>0</iyz>
          </inertia>
        </inertial>
        <visual name="visual">
          <geometry>
            <sphere>
              <radius>0.1</radius>
            </sphere>
          </geometry>
          <material>
            <ambient>0 1 0 1</ambient>
            <diffuse>0 1 0 1</diffuse>
            <specular>0 1 0 1</specular>
            <emissive>0 1 0 1</emissive>
          </material>
        </visual>
        <collision name="collision">
          <geometry>
            <sphere>
              <radius>0.1</radius>
            </sphere>
          </geometry>
        </collision>
      </link>
      <joint name="arm_joint_23" type="revolute">
        <parent>arm_holder</parent>
        <child>arm</child>
        <pose>0 0 0.3 0 0 0</pose>
        <axis>
          <xyz>1 0 0</xyz>
          <limit>
            <lower>-1e4</lower>
            <upper>1e4</upper>
          </limit>
          <dynamics>
            <damping>5</damping>
            <friction>0.0</friction>
          </dynamics>
        </axis>
      </joint>
      <joint name="arm_holder_joint" type="fixed">
        <parent>base_link</parent>
        <child>arm_holder</child>
      </joint>
      <joint name="bob_joint" type="fixed">
        <parent>arm</parent>
        <child>bob</child>
      </joint>
      <plugin filename="libPID_Pendulum" name="simp_pend_ctrl::PID_Pendulum">
        <joint_name>arm_joint_23</joint_name>
        <p_gain>200.0</p_gain>
        <i_gain>0.5</i_gain>
        <d_gain>50.0</d_gain>
        <target_position>3.14159</target_position>
        <theta_0>2.4</theta_0>
      </plugin>
      <!--
            <plugin filename="libGravity_Invert"
                name="simp_pend_ctrl::Gravity_Invert">
                <joint_name>arm_joint_${n}</joint_name>
                <bob_mass>${bob_mass} </bob_mass>
                <arm_length>${arm_length}</arm_length>
                <theta_0>${theta_0} </theta_0>
                <n>${n}</n>
            </plugin>
            -->
    </model>
    <model name="simple_pendulum_24">
      <pose>8 -2 0.76 0 0 0</pose>
      <link name="base_link">
        <pose>0 0 -0.375 0 0 0</pose>
        <inertial>
          <mass>1000</mass>
          <inertia>
            <ixx>52.083333333333336</ixx>
            <iyy>52.083333333333336</iyy>
            <izz>10.416666666666666</izz>
            <ixy>0</ixy>
            <ixz>0</ixz>
            <iyz>0</iyz>
          </inertia>
        </inertial>
        <visual name="visual">
          <geometry>
            <box>
              <size>0.25 0.25 0.75 </size>
            </box>
          </geometry>
          <material>
            <ambient>0 0 1 1</ambient>
            <diffuse>0 0 1 1</diffuse>
            <specular>0 0 1 1</specular>
            <emissive>0 0 1 1</emissive>
          </material>
        </visual>
        <collision name="collision">
          <geometry>
            <box>
              <size>0.25 0.25 0.75 </size>
            </box>
          </geometry>
        </collision>
      </link>
      <link name="arm_holder">
        <pose>-0.0675 0 0 0 0 0</pose>
        <inertial>
          <mass>0.1</mass>
          <inertia>
            <ixx>1.6666666666666669e-06</ixx>
            <iyy>0.00015270833333333334</iyy>
            <izz>0.00015270833333333334</izz>
            <ixy>0</ixy>
            <ixz>0</ixz>
            <iyz>0</iyz>
          </inertia>
        </inertial>
        <visual name="visual">
          <geometry>
            <box>
              <size>0.135 0.01 0.01 </size>
            </box>
          </geometry>
          <material>
            <ambient>0 0 1 1</ambient>
            <diffuse>0 0 1 1</diffuse>
            <specular>0 0 1 1</specular>
            <emissive>0 0 1 1</emissive>
          </material>
        </visual>
        <collision name="collision">
          <geometry>
            <box>
              <size>0.135 0.01 0.01 </size>
            </box>
          </geometry>
        </collision>
      </link>
      <link name="arm">
        <pose>-0.145 -0.2890674556251579 -0.0802496485873762 -1.3 0 0</pose>
        <inertial>
          <mass>0.1</mass>
          <inertia>
            <ixx>0.0030224999999999996</ixx>
            <iyy>0.0030224999999999996</iyy>
            <izz>4.5e-05</izz>
            <ixy>0</ixy>
            <ixz>0</ixz>
            <iyz>0</iyz>
          </inertia>
        </inertial>
        <visual name="visual">
          <geometry>
            <cylinder>
              <radius>0.03</radius>
              <length>0.6</length>
            </cylinder>
          </geometry>
          <material>
            <ambient>1 0 0 1</ambient>
            <diffuse>1 0 0 1</diffuse>
            <specular>1 0 0 1</specular>
            <emissive>1 0 0 1</emissive>
          </material>
        </visual>
        <collision name="collision">
          <geometry>
            <cylinder>
              <radius>0.03</radius>
              <length>0.6</length>
            </cylinder>
          </geometry>
        </collision>
      </link>
      <link name="bob">
        <pose>-0.145 -0.5781349112503158 -0.1604992971747524 0 0 0</pose>
        <inertial>
          <mass>5</mass>
          <inertia>
            <ixx>0.020000000000000004</ixx>
            <iyy>0.020000000000000004</iyy>
            <izz>0.020000000000000004</izz>
            <ixy>0</ixy>
            <ixz>0</ixz>
            <iyz>0</iyz>
          </inertia>
        </inertial>
        <visual name="visual">
          <geometry>
            <sphere>
              <radius>0.1</radius>
            </sphere>
          </geometry>
          <material>
            <ambient>0 1 0 1</ambient>
            <diffuse>0 1 0 1</diffuse>
            <specular>0 1 0 1</specular>
            <emissive>0 1 0 1</emissive>
          </material>
        </visual>
        <collision name="collision">
          <geometry>
            <sphere>
              <radius>0.1</radius>
            </sphere>
          </geometry>
        </collision>
      </link>
      <joint name="arm_joint_24" type="revolute">
        <parent>arm_holder</parent>
        <child>arm</child>
        <pose>0 0 0.3 0 0 0</pose>
        <axis>
          <xyz>1 0 0</xyz>
          <limit>
            <lower>-1e4</lower>
            <upper>1e4</upper>
          </limit>
          <dynamics>
            <damping>5</damping>
            <friction>0.0</friction>
          </dynamics>
        </axis>
      </joint>
      <joint name="arm_holder_joint" type="fixed">
        <parent>base_link</parent>
        <child>arm_holder</child>
      </joint>
      <joint name="bob_joint" type="fixed">
        <parent>arm</parent>
        <child>bob</child>
      </joint>
      <plugin filename="libPID_Pendulum" name="simp_pend_ctrl::PID_Pendulum">
        <joint_name>arm_joint_24</joint_name>
        <p_gain>200.0</p_gain>
        <i_gain>0.5</i_gain>
        <d_gain>50.0</d_gain>
        <target_position>3.14159</target_position>
        <theta_0>-1.3</theta_0>
      </plugin>
      <!--
            <plugin filename="libGravity_Invert"
                name="simp_pend_ctrl::Gravity_Invert">
                <joint_name>arm_joint_${n}</joint_name>
                <bob_mass>${bob_mass} </bob_mass>
                <arm_length>${arm_length}</arm_length>
                <theta_0>${theta_0} </theta_0>
                <n>${n}</n>
            </plugin>
            -->
    </model>
  </world>
</sdf>
