<?xml version="1.0" ?>
<!-- =================================================================================== -->
<!-- |    This document was autogenerated by xacro from world.xacro                    | -->
<!-- |    EDITING THIS FILE BY HAND IS NOT RECOMMENDED                                 | -->
<!-- =================================================================================== -->
<sdf version="1.7">
  <world name="default">
    <model name="ground_plane">
      <static>true</static>
      <link name="link">
        <collision name="collision">
          <geometry>
            <plane>
              <normal>0 0 1</normal>
            </plane>
          </geometry>
        </collision>
        <visual name="visual">
          <geometry>
            <plane>
              <normal>0 0 1</normal>
              <size>100 100</size>
            </plane>
          </geometry>
          <material>
            <ambient>0.8 0.8 0.8 1</ambient>
            <diffuse>0.8 0.8 0.8 1</diffuse>
            <specular>0.8 0.8 0.8 1</specular>
          </material>
        </visual>
      </link>
    </model>
    <model name="simple_pendulum">
      <pose>0 0 1.31 0 0 0</pose>
      <link name="base_link">
        <pose>0 0 -0.65 0 0 0</pose>
        <inertial>
          <mass>1000</mass>
          <inertia>
            <ixx>161.66666666666669</ixx>
            <iyy>161.66666666666669</iyy>
            <izz>41.666666666666664</izz>
            <ixy>0</ixy>
            <ixz>0</ixz>
            <iyz>0</iyz>
          </inertia>
        </inertial>
        <visual name="visual">
          <geometry>
            <box>
              <size>0.5 0.5 1.3 </size>
            </box>
          </geometry>
          <material>
            <ambient>0 0 1 1</ambient>
            <diffuse>0 0 1 1</diffuse>
            <specular>0 0 1 1</specular>
            <emissive>0 0 1 1</emissive>
          </material>
        </visual>
        <collision name="collision">
          <geometry>
            <box>
              <size>0.5 0.5 1.3 </size>
            </box>
          </geometry>
        </collision>
      </link>
      <link name="arm_holder">
        <pose>0.13 0 0 0 0 0</pose>
        <inertial>
          <mass>0.1</mass>
          <inertia>
            <ixx>1.6666666666666669e-06</ixx>
            <iyy>0.0005641666666666668</iyy>
            <izz>0.0005641666666666668</izz>
            <ixy>0</ixy>
            <ixz>0</ixz>
            <iyz>0</iyz>
          </inertia>
        </inertial>
        <visual name="visual">
          <geometry>
            <box>
              <size>0.26 0.01 0.01 </size>
            </box>
          </geometry>
          <material>
            <ambient>0 0 1 1</ambient>
            <diffuse>0 0 1 1</diffuse>
            <specular>0 0 1 1</specular>
            <emissive>0 0 1 1</emissive>
          </material>
        </visual>
        <collision name="collision">
          <geometry>
            <box>
              <size>0.26 0.01 0.01 </size>
            </box>
          </geometry>
        </collision>
      </link>
      <link name="arm">
        <pose>0.27 0.5 0 1.570795 0 0</pose>
        <inertial>
          <mass>0.1</mass>
          <inertia>
            <ixx>0.008355833333333333</ixx>
            <iyy>0.008355833333333333</iyy>
            <izz>4.5e-05</izz>
            <ixy>0</ixy>
            <ixz>0</ixz>
            <iyz>0</iyz>
          </inertia>
        </inertial>
        <visual name="visual">
          <geometry>
            <cylinder>
              <radius>0.03</radius>
              <length>1.0</length>
            </cylinder>
          </geometry>
          <material>
            <ambient>1 0 0 1</ambient>
            <diffuse>1 0 0 1</diffuse>
            <specular>1 0 0 1</specular>
            <emissive>1 0 0 1</emissive>
          </material>
        </visual>
        <collision name="collision">
          <geometry>
            <cylinder>
              <radius>0.03</radius>
              <length>1.0</length>
            </cylinder>
          </geometry>
        </collision>
      </link>
      <link name="bob">
        <pose>0.27 1.0 0 0 0 0</pose>
        <inertial>
          <mass>10</mass>
          <inertia>
            <ixx>0.04000000000000001</ixx>
            <iyy>0.04000000000000001</iyy>
            <izz>0.04000000000000001</izz>
            <ixy>0</ixy>
            <ixz>0</ixz>
            <iyz>0</iyz>
          </inertia>
        </inertial>
        <visual name="visual">
          <geometry>
            <sphere>
              <radius>0.1</radius>
            </sphere>
          </geometry>
          <material>
            <ambient>0 1 0 1</ambient>
            <diffuse>0 1 0 1</diffuse>
            <specular>0 1 0 1</specular>
            <emissive>0 1 0 1</emissive>
          </material>
        </visual>
        <collision name="collision">
          <geometry>
            <sphere>
              <radius>0.1</radius>
            </sphere>
          </geometry>
        </collision>
      </link>
      <joint name="arm_joint" type="revolute">
        <parent>arm_holder</parent>
        <child>arm</child>
        <pose>0 0 0.5 0 0 0</pose>
        <axis>
          <xyz>1 0 0</xyz>
          <limit>
            <lower>-1e16</lower>
            <upper>1e16</upper>
          </limit>
        </axis>
        <pose>0 0 0 0 0 0</pose>
      </joint>
      <joint name="arm_holder_joint" type="fixed">
        <parent>base_link</parent>
        <child>arm_holder</child>
      </joint>
      <joint name="bob_joint" type="fixed">
        <parent>arm</parent>
        <child>bob</child>
      </joint>
    </model>
  </world>
</sdf>
