<?xml version="1.0" ?>
<!-- =================================================================================== -->
<!-- |    This document was autogenerated by xacro from worlds/world.xacro             | -->
<!-- |    EDITING THIS FILE BY HAND IS NOT RECOMMENDED                                 | -->
<!-- =================================================================================== -->
<sdf version="1.7">
  <world name="default">
    <gravity> 0 0 -9.81 </gravity>
    <model name="ground_plane">
      <static>true</static>
      <link name="link">
        <collision name="collision">
          <geometry>
            <plane>
              <normal>0 0 1</normal>
            </plane>
          </geometry>
        </collision>
        <visual name="visual">
          <geometry>
            <plane>
              <normal>0 0 1</normal>
              <size>100 100</size>
            </plane>
          </geometry>
          <material>
            <ambient>0.8 0.8 0.8 1</ambient>
            <diffuse>0.8 0.8 0.8 1</diffuse>
            <specular>0.8 0.8 0.8 1</specular>
          </material>
        </visual>
      </link>
    </model>
    <model name="double_pendulum_0">
      <pose>0 0 2.6499999999999995 0 0 0</pose>
      <link name="base_link">
        <pose>0 0 -2.6199999999999997 0 0 0</pose>
        <inertial>
          <mass>2000</mass>
          <inertia>
            <ixx>500.26666666666665</ixx>
            <iyy>500.26666666666665</iyy>
            <izz>1000.0</izz>
            <ixy>0</ixy>
            <ixz>0</ixz>
            <iyz>0</iyz>
          </inertia>
        </inertial>
        <visual name="visual">
          <geometry>
            <cylinder>
              <radius>1</radius>
              <length>0.04</length>
            </cylinder>
          </geometry>
          <material>
            <ambient>0.3254901960784314 0.33725490196078434 1.0 1</ambient>
            <diffuse>0.3254901960784314 0.33725490196078434 1.0 1</diffuse>
            <specular>0.3254901960784314 0.33725490196078434 1.0 1</specular>
            <emissive>0.3254901960784314 0.33725490196078434 1.0 1</emissive>
          </material>
        </visual>
        <collision name="collision">
          <geometry>
            <cylinder>
              <radius>1</radius>
              <length>0.04</length>
            </cylinder>
          </geometry>
        </collision>
      </link>
      <link name="stand_1">
        <pose>0.3 0 -1.275 0 0 0</pose>
        <inertial>
          <mass>2000</mass>
          <inertia>
            <ixx>1172.0833333333328</ixx>
            <iyy>1172.0833333333328</iyy>
            <izz>3.333333333333334</izz>
            <ixy>0</ixy>
            <ixz>0</ixz>
            <iyz>0</iyz>
          </inertia>
        </inertial>
        <visual name="visual">
          <geometry>
            <box>
              <size>0.1 0.1 2.6499999999999995 </size>
            </box>
          </geometry>
          <material>
            <ambient>0.21568627450980393 0.5490196078431373 0.9058823529411765 1</ambient>
            <diffuse>0.21568627450980393 0.5490196078431373 0.9058823529411765 1</diffuse>
            <specular>0.21568627450980393 0.5490196078431373 0.9058823529411765 1</specular>
            <emissive>0.21568627450980393 0.5490196078431373 0.9058823529411765 1</emissive>
          </material>
        </visual>
        <collision name="collision">
          <geometry>
            <box>
              <size>0.1 0.1 2.6499999999999995 </size>
            </box>
          </geometry>
        </collision>
      </link>
      <link name="stand_2">
        <pose>-0.3 0 -1.275 0 0 0</pose>
        <inertial>
          <mass>2000</mass>
          <inertia>
            <ixx>1172.0833333333328</ixx>
            <iyy>1172.0833333333328</iyy>
            <izz>3.333333333333334</izz>
            <ixy>0</ixy>
            <ixz>0</ixz>
            <iyz>0</iyz>
          </inertia>
        </inertial>
        <visual name="visual">
          <geometry>
            <box>
              <size>0.1 0.1 2.6499999999999995 </size>
            </box>
          </geometry>
          <material>
            <ambient>0.21568627450980393 0.5490196078431373 0.9058823529411765 1</ambient>
            <diffuse>0.21568627450980393 0.5490196078431373 0.9058823529411765 1</diffuse>
            <specular>0.21568627450980393 0.5490196078431373 0.9058823529411765 1</specular>
            <emissive>0.21568627450980393 0.5490196078431373 0.9058823529411765 1</emissive>
          </material>
        </visual>
        <collision name="collision">
          <geometry>
            <box>
              <size>0.1 0.1 2.6499999999999995 </size>
            </box>
          </geometry>
        </collision>
      </link>
      <link name="arm_bearing_1_0">
        <pose>0 0 0 0 1.570795 0</pose>
        <inertial>
          <mass>0.01</mass>
          <inertia>
            <ixx>0.00021458333333333334</ixx>
            <iyy>0.00021458333333333334</iyy>
            <izz>1.2500000000000002e-05</izz>
            <ixy>0</ixy>
            <ixz>0</ixz>
            <iyz>0</iyz>
          </inertia>
        </inertial>
        <visual name="visual">
          <geometry>
            <cylinder>
              <radius>0.05</radius>
              <length>0.5</length>
            </cylinder>
          </geometry>
          <material>
            <ambient>0.403921568627451 0.7764705882352941 0.8901960784313725 1</ambient>
            <diffuse>0.403921568627451 0.7764705882352941 0.8901960784313725 1</diffuse>
            <specular>0.403921568627451 0.7764705882352941 0.8901960784313725 1</specular>
            <emissive>0.403921568627451 0.7764705882352941 0.8901960784313725 1</emissive>
          </material>
        </visual>
        <collision name="collision">
          <geometry>
            <cylinder>
              <radius>0.05</radius>
              <length>0.5</length>
            </cylinder>
          </geometry>
        </collision>
      </link>
      <link name="arm_bearing_2_0">
        <pose>0 0 -1.4 0 1.570795 0</pose>
        <inertial>
          <mass>10</mass>
          <inertia>
            <ixx>0.21458333333333335</ixx>
            <iyy>0.21458333333333335</iyy>
            <izz>0.012500000000000002</izz>
            <ixy>0</ixy>
            <ixz>0</ixz>
            <iyz>0</iyz>
          </inertia>
        </inertial>
        <visual name="visual">
          <geometry>
            <cylinder>
              <radius>0.05</radius>
              <length>0.5</length>
            </cylinder>
          </geometry>
          <material>
            <ambient>0.403921568627451 0.7764705882352941 0.8901960784313725 1</ambient>
            <diffuse>0.403921568627451 0.7764705882352941 0.8901960784313725 1</diffuse>
            <specular>0.403921568627451 0.7764705882352941 0.8901960784313725 1</specular>
            <emissive>0.403921568627451 0.7764705882352941 0.8901960784313725 1</emissive>
          </material>
        </visual>
        <collision name="collision">
          <geometry>
            <cylinder>
              <radius>0.05</radius>
              <length>0.5</length>
            </cylinder>
          </geometry>
        </collision>
      </link>
      <link name="bob_0">
        <pose>0 0 -2.3 0 0 0</pose>
        <inertial>
          <mass>10</mass>
          <inertia>
            <ixx>0.04000000000000001</ixx>
            <iyy>0.04000000000000001</iyy>
            <izz>0.04000000000000001</izz>
            <ixy>0</ixy>
            <ixz>0</ixz>
            <iyz>0</iyz>
          </inertia>
        </inertial>
        <visual name="visual">
          <geometry>
            <sphere>
              <radius>0.1</radius>
            </sphere>
          </geometry>
          <material>
            <ambient>0.403921568627451 0.7764705882352941 0.8901960784313725 1</ambient>
            <diffuse>0.403921568627451 0.7764705882352941 0.8901960784313725 1</diffuse>
            <specular>0.403921568627451 0.7764705882352941 0.8901960784313725 1</specular>
            <emissive>0.403921568627451 0.7764705882352941 0.8901960784313725 1</emissive>
          </material>
        </visual>
        <collision name="collision">
          <geometry>
            <sphere>
              <radius>0.1</radius>
            </sphere>
          </geometry>
        </collision>
      </link>
      <link name="arm_1_0">
        <pose>0.225 0 -0.7 0 0 0</pose>
        <inertial>
          <mass>0.01</mass>
          <inertia>
            <ixx>0.0018765625</ixx>
            <iyy>0.0018765625</iyy>
            <izz>3.1250000000000006e-06</izz>
            <ixy>0</ixy>
            <ixz>0</ixz>
            <iyz>0</iyz>
          </inertia>
        </inertial>
        <visual name="visual">
          <geometry>
            <cylinder>
              <radius>0.025</radius>
              <length>1.5</length>
            </cylinder>
          </geometry>
          <material>
            <ambient>0.8745098039215686 0.9607843137254902 1.0 1</ambient>
            <diffuse>0.8745098039215686 0.9607843137254902 1.0 1</diffuse>
            <specular>0.8745098039215686 0.9607843137254902 1.0 1</specular>
            <emissive>0.8745098039215686 0.9607843137254902 1.0 1</emissive>
          </material>
        </visual>
        <collision name="collision">
          <geometry>
            <cylinder>
              <radius>0.025</radius>
              <length>1.5</length>
            </cylinder>
          </geometry>
        </collision>
      </link>
      <link name="arm_2_0">
        <pose>-0.225 0 -0.7 0 0 0</pose>
        <inertial>
          <mass>0.01</mass>
          <inertia>
            <ixx>0.0018765625</ixx>
            <iyy>0.0018765625</iyy>
            <izz>3.1250000000000006e-06</izz>
            <ixy>0</ixy>
            <ixz>0</ixz>
            <iyz>0</iyz>
          </inertia>
        </inertial>
        <visual name="visual">
          <geometry>
            <cylinder>
              <radius>0.025</radius>
              <length>1.5</length>
            </cylinder>
          </geometry>
          <material>
            <ambient>0.8745098039215686 0.9607843137254902 1.0 1</ambient>
            <diffuse>0.8745098039215686 0.9607843137254902 1.0 1</diffuse>
            <specular>0.8745098039215686 0.9607843137254902 1.0 1</specular>
            <emissive>0.8745098039215686 0.9607843137254902 1.0 1</emissive>
          </material>
        </visual>
        <collision name="collision">
          <geometry>
            <cylinder>
              <radius>0.025</radius>
              <length>1.5</length>
            </cylinder>
          </geometry>
        </collision>
      </link>
      <link name="bob_arm_0">
        <pose>0 0 -1.8499999999999999 0 0 0</pose>
        <inertial>
          <mass>0.01</mass>
          <inertia>
            <ixx>0.0006765625000000001</ixx>
            <iyy>0.0006765625000000001</iyy>
            <izz>3.1250000000000006e-06</izz>
            <ixy>0</ixy>
            <ixz>0</ixz>
            <iyz>0</iyz>
          </inertia>
        </inertial>
        <visual name="visual">
          <geometry>
            <cylinder>
              <radius>0.025</radius>
              <length>0.9</length>
            </cylinder>
          </geometry>
          <material>
            <ambient>0.8745098039215686 0.9607843137254902 1.0 1</ambient>
            <diffuse>0.8745098039215686 0.9607843137254902 1.0 1</diffuse>
            <specular>0.8745098039215686 0.9607843137254902 1.0 1</specular>
            <emissive>0.8745098039215686 0.9607843137254902 1.0 1</emissive>
          </material>
        </visual>
        <collision name="collision">
          <geometry>
            <cylinder>
              <radius>0.025</radius>
              <length>0.9</length>
            </cylinder>
          </geometry>
        </collision>
      </link>
      <joint name="base_link_stand_1_joint" type="fixed">
        <parent>base_link</parent>
        <child>stand_1</child>
      </joint>
      <joint name="base_link_stand_2_joint" type="fixed">
        <parent>base_link</parent>
        <child>stand_2</child>
      </joint>
      <joint name="stand_arm_bearing_1_joint" type="fixed">
        <parent>stand_1</parent>
        <child>arm_bearing_1_0</child>
      </joint>
      <joint name="bearing_2_arm_1_joint" type="fixed">
        <parent>arm_1_0</parent>
        <child>arm_bearing_2_0</child>
      </joint>
      <joint name="bearing_2_arm_2_joint" type="fixed">
        <parent>arm_bearing_2_0</parent>
        <child>arm_2_0</child>
      </joint>
      <joint name="bob_arm_bob_joint" type="fixed">
        <parent>bob_arm_0</parent>
        <child>bob_0</child>
      </joint>
      <joint name="revolute_1_0" type="revolute">
        <parent>arm_bearing_1_0</parent>
        <child>arm_1_0</child>
        <pose>0 0 0.7 0 0 0</pose>
        <axis>
          <xyz> 1 0 0 </xyz>
          <limit/>
          <dynamics>
            <damping>10</damping>
            <friction>5</friction>
          </dynamics>
        </axis>
      </joint>
      <joint name="revolute_2_0" type="revolute">
        <parent>arm_bearing_2_0</parent>
        <child>bob_arm_0</child>
        <pose>0 0 0.45 0 -3.14159 0</pose>
        <axis>
          <xyz> 1 0 0 </xyz>
          <limit/>
          <dynamics>
            <damping>10</damping>
            <friction>5</friction>
          </dynamics>
        </axis>
      </joint>
      <plugin filename="libPIDController" name="dbl_pend_ctrl::PIDController">
        <joint_1_name>revolute_1_0</joint_1_name>
        <joint_2_name>revolute_2_0</joint_2_name>
        <P_gain_1>500</P_gain_1>
        <I_gain_1>10</I_gain_1>
        <D_gain_1>100</D_gain_1>
        <P_gain_2>100</P_gain_2>
        <I_gain_2>20</I_gain_2>
        <D_gain_2>30</D_gain_2>
        <theta_1_0>2.2</theta_1_0>
        <theta_2_0>1.4</theta_2_0>
      </plugin>
      <!--
            <plugin filename='libFeedbackCancellation'
                name = "dbl_pend_ctrl::FeedbackCancellation">
                <joint_1_name>revolute_1_${n}</joint_1_name>
                <joint_2_name>revolute_2_${n}</joint_2_name>

                <mass_1>${mass_1}</mass_1>
                <mass_2>${mass_2}</mass_2>

                <length_1>${length_1}</length_1>
                <length_2>${length_2}</length_2>

                <theta_1_0>${theta_1}</theta_1_0>
                <theta_2_0>${theta_2}</theta_2_0>
            </plugin>
            -->
    </model>
  </world>
</sdf>
